Workbook

Sheet RAB

Sheet IURAN WARGA
A1: DAFTAR SIMPANAN ANGGOTA DANA KEBERSAMAAN PEGAWAI 625
A2: 1 | B2: 2 | F2: =#REF!+1 -> #REF! | G2: =F2+1 -> #REF! | H2: =#REF!+1 -> #REF! | I2: =#REF!+1 -> #REF! | J2: =#REF!+1 -> #REF! | K2: =#REF!+1 -> #REF! | L2: =#REF!+1 -> #REF! | M2: =#REF!+1 -> #REF! | N2: =#REF!+1 -> #REF! | O2: =#REF!+1 -> #REF! | ... S2: =#REF!+1 -> #REF! | T2: =S2+1 -> #REF! | U2: =#REF!+1 -> #REF! | V2: =#REF!+1 -> #REF! | W2: =#REF!+1 -> #REF! | X2: =#REF!+1 -> #REF! | Y2: =#REF!+1 -> #REF! | Z2: =#REF!+1 -> #REF! | AA2: =#REF!+1 -> #REF! | AB2: =#REF!+1 -> #REF! | ... AE2: =#REF!+1 -> #REF! | BG2: =#REF!+1 -> #REF!
A3: TAHUN | G3: TAHUN 2024 | T3: TAHUN 2025 | AG3: TAHUN 2026 | AT3: TAHUN 2027
A4: No | B4: Blok | C4: Nama Pemilik | D4: Jenis Hunian | E4: Kondisi | F4: Saldo | G4: 1 | H4: 2 | I4: 3 | J4: 4 | K4: 5 | L4: 6 | M4: 7 | N4: 8 | O4: 9 | P4: 10 | Q4: 11 | R4: 12 | S4: Saldo Akhir | T4: 1 | U4: 2 | V4: 3 | W4: 4 | X4: 5 | Y4: 6 | Z4: 7 | AA4: 8 | AB4: 9 | AC4: 10 | AD4: 11 | AE4: 12 | AF4: Saldo | AG4: 1 | AH4: 2 | AI4: 3 | AJ4: 4 | AK4: 5 | AL4: 6 | AM4: 7 | AN4: 8 | AO4: 9 | AP4: 10 | AQ4: 11 | AR4: 12 | AS4: Saldo Akhir | AT4: 1 | AU4: 2 | AV4: 3 | AW4: 4 | AX4: 5 | AY4: 6 | AZ4: 7 | BA4: 8 | BB4: 9 | BC4: 10 | BD4: 11 | BE4: 12 | BF4: Saldo | BG4: KETERANGAN
A5: 1 | B5: A-01 | C5: Leni | D5: Tanah Kosong | E5: Proses Bangun | F5: 0 | S5: =SUM(G5:R5) -> 0 | AF5: =SUM(T5:AE5) -> 0 | AS5: =SUM(AG5:AR5) -> 0 | BF5: =SUM(AT5:BE5) -> 0 | BH5: 0 | BI5: =S5-BH5 -> 0
A6: =A5+1 -> 2 | B6: A-02 | C6: Muhammad Mursyidi | D6: Rumah Tinggal | E6: Dihuni pribadi | F6: 0 | S6: =SUM(G6:R6) -> 0 | T6: 100000 | U6: 100000 | V6: 100000 | W6: 100000 | X6: 100000 | Y6: 100000 | Z6: 100000 | AA6: 100000 | AB6: 100000 | AC6: 100000 | AD6: 100000 | AE6: 100000 | AF6: =SUM(T6:AE6) -> 1200000 | AG6: 100000 | AH6: 100000 | AI6: 100000 | AJ6: 100000 | AK6: 100000 | AS6: =SUM(AG6:AR6) -> 500000 | BF6: =SUM(AT6:BE6) -> 0 | BH6: 0 | BI6: =S6-BH6 -> 0
A7: =A6+1 -> 3 | B7: A-03 | C7: Leni | D7: Rumah Tinggal | E7: Dikontrakkan | F7: 0 | S7: =SUM(G7:R7) -> 0 | T7: 100000 | AF7: =SUM(T7:AE7) -> 100000 | AG7: 100000 | AH7: 100000 | AI7: 100000 | AS7: =SUM(AG7:AR7) -> 300000 | BF7: =SUM(AT7:BE7) -> 0 | BH7: 0 | BI7: =S7-BH7 -> 0
A8: =A7+1 -> 4 | B8: A-04 | C8: Sutiaji | D8: Rumah Tinggal | E8: kosong | F8: 0 | S8: =SUM(G8:R8) -> 0 | T8: 100000 | U8: 100000 | V8: 100000 | W8: 100000 | X8: 100000 | Y8: 100000 | Z8: 100000 | AA8: 100000 | AB8: 100000 | AC8: 100000 | AD8: 100000 | AE8: 100000 | AF8: =SUM(T8:AE8) -> 1200000 | AG8: 100000 | AH8: 100000 | AI8: 100000 | AJ8: 100000 | AK8: 100000 | AS8: =SUM(AG8:AR8) -> 500000 | BF8: =SUM(AT8:BE8) -> 0 | BH8: 0 | BI8: =S8-BH8 -> 0
A9: =A8+1 -> 5 | B9: A-05 | C9: Hendro | D9: Rumah Tinggal | E9: kosong | F9: 0 | G9: 100000 | H9: 100000 | I9: 100000 | J9: 100000 | K9: 100000 | S9: =SUM(G9:R9) -> 500000 | X9: 100000 | Y9: 100000 | Z9: 100000 | AA9: 100000 | AB9: 100000 | AC9: 100000 | AD9: 100000 | AE9: 100000 | AF9: =SUM(T9:AE9) -> 800000 | AG9: 100000 | AH9: 100000 | AI9: 100000 | AJ9: 100000 | AS9: =SUM(AG9:AR9) -> 400000 | BF9: =SUM(AT9:BE9) -> 0 | BH9: 0 | BI9: =S9-BH9 -> 500000
A10: =A9+1 -> 6 | B10: A-06 | C10: Lukman Isya | D10: Rumah Tinggal | E10: Dihuni sendiri | F10: 0 | S10: =SUM(G10:R10) -> 0 | T10: 100000 | U10: 100000 | V10: 100000 | W10: 100000 | X10: 100000 | Y10: 100000 | Z10: 100000 | AA10: 100000 | AB10: 100000 | AC10: 100000 | AD10: 100000 | AE10: 100000 | AF10: =SUM(T10:AE10) -> 1200000 | AG10: 100000 | AH10: 100000 | AI10: 100000 | AJ10: 100000 | AK10: 100000 | AL10: 100000 | AM10: 100000 | AN10: 100000 | AO10: 100000 | AP10: 100000 | AQ10: 100000 | AR10: 100000 | AS10: =SUM(AG10:AR10) -> 1200000 | BF10: =SUM(AT10:BE10) -> 0 | BH10: 0 | BI10: =S10-BH10 -> 0
A11: =A10+1 -> 7 | B11: A-07 | C11: Ari Cahya Permata | D11: Rumah Tinggal | E11: Dikontrakkan | F11: 0 | S11: =SUM(G11:R11) -> 0 | T11: 100000 | U11: 100000 | V11: 100000 | W11: 100000 | X11: 100000 | Y11: 100000 | Z11: 100000 | AA11: 100000 | AB11: 100000 | AC11: 100000 | AD11: 100000 | AE11: 100000 | AF11: =SUM(T11:AE11) -> 1200000 | AG11: 100000 | AH11: 100000 | AI11: 100000 | AJ11: 150000 | AK11: 100000 | AL11: 100000 | AM11: 100000 | AN11: 100000 | AO11: 100000 | AP11: 100000 | AQ11: 100000 | AR11: 100000 | AS11: =SUM(AG11:AR11) -> 1250000 | BF11: =SUM(AT11:BE11) -> 0 | BH11: 0 | BI11: =S11-BH11 -> 0
A12: =A11+1 -> 8 | B12: A-08 | C12: Lusi | D12: Rumah Tinggal | E12: kosong | F12: 0 | S12: =SUM(G12:R12) -> 0 | T12: 100000 | U12: 100000 | V12: 100000 | W12: 100000 | X12: 100000 | Y12: 100000 | Z12: 100000 | AA12: 100000 | AB12: 100000 | AC12: 100000 | AD12: 100000 | AE12: 100000 | AF12: =SUM(T12:AE12) -> 1200000 | AS12: =SUM(AG12:AR12) -> 0 | BF12: =SUM(AT12:BE12) -> 0 | BH12: 0 | BI12: =S12-BH12 -> 0
A13: =A12+1 -> 9 | B13: A-09 | C13: Rahmad | D13: Rumah Tinggal | E13: Kantor | F13: 0 | S13: =SUM(G13:R13) -> 0 | T13: 100000 | U13: 100000 | V13: 100000 | W13: 100000 | X13: 100000 | Y13: 100000 | Z13: 100000 | AA13: 100000 | AB13: 100000 | AC13: 100000 | AD13: 100000 | AE13: 100000 | AF13: =SUM(T13:AE13) -> 1200000 | AG13: 100000 | AH13: 100000 | AI13: 100000 | AJ13: 100000 | AS13: =SUM(AG13:AR13) -> 400000 | BF13: =SUM(AT13:BE13) -> 0 | BH13: 0 | BI13: =S13-BH13 -> 0
A14: =A13+1 -> 10 | B14: A-10 | C14: Siregar | D14: Rumah Tinggal | E14: Dihuni sendiri | F14: 0 | S14: =SUM(G14:R14) -> 0 | T14: 100000 | U14: 100000 | V14: 100000 | W14: 100000 | X14: 100000 | Y14: 100000 | Z14: 100000 | AA14: 100000 | AB14: 100000 | AC14: 100000 | AD14: 100000 | AE14: 100000 | AF14: =SUM(T14:AE14) -> 1200000 | AS14: =SUM(AG14:AR14) -> 0 | BF14: =SUM(AT14:BE14) -> 0 | BH14: 0 | BI14: =S14-BH14 -> 0
A15: =A14+1 -> 11 | B15: A-11 | C15: Rahmad | D15: Rumah Tinggal | E15: Kantor | F15: 0 | S15: =SUM(G15:R15) -> 0 | AF15: =SUM(T15:AE15) -> 0 | AI15: 100000 | AJ15: 100000 | AS15: =SUM(AG15:AR15) -> 200000 | BF15: =SUM(AT15:BE15) -> 0 | BH15: 0 | BI15: =S15-BH15 -> 0
A16: =A15+1 -> 12 | B16: A-12 | C16: Rahman | D16: Rumah Tinggal | E16: Dihuni sendiri | F16: 0 | S16: =SUM(G16:R16) -> 0 | T16: 100000 | U16: 100000 | V16: 100000 | W16: 100000 | X16: 100000 | Y16: 100000 | Z16: 100000 | AA16: 100000 | AB16: 100000 | AC16: 100000 | AD16: 100000 | AE16: 100000 | AF16: =SUM(T16:AE16) -> 1200000 | AG16: 100000 | AH16: 100000 | AI16: 100000 | AJ16: 100000 | AK16: 100000 | AL16: 100000 | AS16: =SUM(AG16:AR16) -> 600000 | BF16: =SUM(AT16:BE16) -> 0 | BH16: 0 | BI16: =S16-BH16 -> 0
A17: =A16+1 -> 13 | B17: A-13 | C17: Musholla | D17: Mushola | E17: Mushola | F17: 0 | S17: =SUM(G17:R17) -> 0 | AF17: =SUM(T17:AE17) -> 0 | AS17: =SUM(AG17:AR17) -> 0 | BF17: =SUM(AT17:BE17) -> 0 | BH17: 0 | BI17: =S17-BH17 -> 0
A18: =A17+1 -> 14 | B18: A-14 | C18: Agung | D18: Rumah Tinggal | E18: Dihuni sendiri | F18: 0 | S18: =SUM(G18:R18) -> 0 | T18: 100000 | U18: 100000 | V18: 100000 | W18: 100000 | X18: 100000 | Y18: 100000 | Z18: 100000 | AA18: 100000 | AB18: 100000 | AC18: 100000 | AD18: 100000 | AE18: 100000 | AF18: =SUM(T18:AE18) -> 1200000 | AG18: 100000 | AH18: 100000 | AI18: 100000 | AJ18: 100000 | AK18: 100000 | AS18: =SUM(AG18:AR18) -> 500000 | BF18: =SUM(AT18:BE18) -> 0 | BH18: 0 | BI18: =S18-BH18 -> 0
A19: =A18+1 -> 15 | B19: A-15 | C19: Sindu | D19: Rumah Tinggal | E19: Dihuni sendiri | F19: 0 | S19: =SUM(G19:R19) -> 0 | T19: 100000 | U19: 100000 | V19: 100000 | W19: 100000 | X19: 100000 | Y19: 100000 | Z19: 100000 | AA19: 100000 | AB19: 100000 | AC19: 100000 | AD19: 100000 | AE19: 100000 | AF19: =SUM(T19:AE19) -> 1200000 | AG19: 100000 | AH19: 100000 | AI19: 100000 | AJ19: 100000 | AK19: 100000 | AL19: 100000 | AM19: 100000 | AN19: 100000 | AO19: 100000 | AS19: =SUM(AG19:AR19) -> 900000 | BF19: =SUM(AT19:BE19) -> 0 | BH19: 0 | BI19: =S19-BH19 -> 0
A20: =A19+1 -> 16 | B20: A-16 | C20: Andrianto Budiaji | D20: Rumah Tinggal | E20: Dihuni sendiri | F20: 0 | S20: =SUM(G20:R20) -> 0 | T20: 100000 | U20: 100000 | V20: 100000 | W20: 100000 | X20: 100000 | Y20: 100000 | Z20: 100000 | AA20: 100000 | AB20: 100000 | AC20: 100000 | AD20: 100000 | AE20: 100000 | AF20: =SUM(T20:AE20) -> 1200000 | AG20: 100000 | AH20: 100000 | AI20: 100000 | AJ20: 100000 | AK20: 100000 | AS20: =SUM(AG20:AR20) -> 500000 | BF20: =SUM(AT20:BE20) -> 0 | BH20: 0 | BI20: =S20-BH20 -> 0
A21: =A20+1 -> 17 | B21: A-17 | C21: Adib Abror | D21: Rumah Tinggal | E21: Dihuni sendiri | F21: 0 | S21: =SUM(G21:R21) -> 0 | T21: 100000 | U21: 100000 | V21: 100000 | W21: 100000 | X21: 100000 | Y21: 100000 | Z21: 100000 | AA21: 100000 | AB21: 100000 | AC21: 100000 | AD21: 100000 | AE21: 100000 | AF21: =SUM(T21:AE21) -> 1200000 | AG21: 100000 | AH21: 100000 | AI21: 100000 | AJ21: 100000 | AK21: 100000 | AL21: 100000 | AM21: 100000 | AN21: 100000 | AO21: 100000 | AP21: 100000 | AQ21: 100000 | AR21: 100000 | AS21: =SUM(AG21:AR21) -> 1200000 | BF21: =SUM(AT21:BE21) -> 0 | BH21: 0 | BI21: =S21-BH21 -> 0
A22: =A21+1 -> 18 | B22: A-18 | C22: Roti | D22: Rumah Tinggal | E22: kosong | F22: 0 | S22: =SUM(G22:R22) -> 0 | T22: 100000 | U22: 100000 | V22: 100000 | W22: 100000 | X22: 100000 | Y22: 100000 | Z22: 100000 | AA22: 100000 | AF22: =SUM(T22:AE22) -> 800000 | AS22: =SUM(AG22:AR22) -> 0 | BF22: =SUM(AT22:BE22) -> 0 | BH22: 0 | BI22: =S22-BH22 -> 0
A23: =A22+1 -> 19 | B23: A-19 | C23: Chandra | D23: Rumah Tinggal | E23: Dihuni sendiri | F23: 0 | S23: =SUM(G23:R23) -> 0 | T23: 100000 | U23: 100000 | V23: 100000 | W23: 100000 | X23: 100000 | Y23: 100000 | Z23: 100000 | AA23: 100000 | AB23: 100000 | AC23: 100000 | AD23: 100000 | AE23: 100000 | AF23: =SUM(T23:AE23) -> 1200000 | AG23: 100000 | AH23: 100000 | AI23: 100000 | AJ23: 100000 | AK23: 100000 | AS23: =SUM(AG23:AR23) -> 500000 | BF23: =SUM(AT23:BE23) -> 0 | BH23: 0 | BI23: =S23-BH23 -> 0
A24: =A23+1 -> 20 | B24: A-20 | C24: Zulkarnain | D24: Rumah Tinggal | E24: Dihuni anak | F24: 0 | S24: =SUM(G24:R24) -> 0 | T24: 100000 | U24: 100000 | V24: 100000 | W24: 100000 | X24: 100000 | Y24: 100000 | Z24: 100000 | AA24: 100000 | AB24: 100000 | AC24: 100000 | AD24: 100000 | AE24: 100000 | AF24: =SUM(T24:AE24) -> 1200000 | AG24: 100000 | AH24: 100000 | AI24: 100000 | AJ24: 100000 | AS24: =SUM(AG24:AR24) -> 400000 | BF24: =SUM(AT24:BE24) -> 0 | BH24: 0 | BI24: =S24-BH24 -> 0
A25: =A24+1 -> 21 | B25: A-21 | C25: 0 | F25: 0 | S25: =SUM(G25:R25) -> 0 | T25: 100000 | U25: 100000 | V25: 100000 | W25: 100000 | AF25: =SUM(T25:AE25) -> 400000 | AS25: =SUM(AG25:AR25) -> 0 | BF25: =SUM(AT25:BE25) -> 0 | BH25: 0 | BI25: =S25-BH25 -> 0
A26: =A25+1 -> 22 | B26: A-22 | C26: 0 | F26: 0 | S26: =SUM(G26:R26) -> 0 | T26: 100000 | U26: 100000 | V26: 100000 | W26: 100000 | X26: 100000 | AF26: =SUM(T26:AE26) -> 500000 | AG26: 100000 | AH26: 100000 | AI26: 100000 | AJ26: 100000 | AS26: =SUM(AG26:AR26) -> 400000 | BF26: =SUM(AT26:BE26) -> 0 | BH26: 0 | BI26: =S26-BH26 -> 0
A27: =A26+1 -> 23 | B27: A-23 | C27: Indra Septi | D27: Rumah Tinggal | E27: Dihuni sendiri | F27: 0 | S27: =SUM(G27:R27) -> 0 | T27: 100000 | U27: 100000 | V27: 100000 | W27: 100000 | X27: 100000 | Y27: 100000 | Z27: 100000 | AA27: 100000 | AB27: 100000 | AC27: 100000 | AD27: 100000 | AE27: 100000 | AF27: =SUM(T27:AE27) -> 1200000 | AG27: 100000 | AH27: 100000 | AI27: 100000 | AJ27: 100000 | AK27: 100000 | AL27: 100000 | AM27: 100000 | AN27: 100000 | AO27: 100000 | AP27: 100000 | AQ27: 100000 | AR27: 100000 | AS27: =SUM(AG27:AR27) -> 1200000 | BF27: =SUM(AT27:BE27) -> 0 | BH27: 0 | BI27: =S27-BH27 -> 0
A28: =A27+1 -> 24 | B28: A-24 | C28: Ghozaimi | D28: Rumah Tinggal | E28: Dihuni sendiri | F28: 0 | S28: =SUM(G28:R28) -> 0 | T28: 100000 | U28: 100000 | V28: 100000 | W28: 100000 | X28: 100000 | Y28: 100000 | Z28: 100000 | AA28: 100000 | AB28: 100000 | AC28: 100000 | AD28: 100000 | AE28: 100000 | AF28: =SUM(T28:AE28) -> 1200000 | AG28: 100000 | AH28: 100000 | AI28: 100000 | AJ28: 100000 | AS28: =SUM(AG28:AR28) -> 400000 | BF28: =SUM(AT28:BE28) -> 0 | BH28: 0 | BI28: =S28-BH28 -> 0
A29: =A28+1 -> 25 | B29: A-25 | C29: 0 | F29: 0 | S29: =SUM(G29:R29) -> 0 | T29: 100000 | U29: 100000 | V29: 100000 | W29: 100000 | X29: 100000 | Y29: 100000 | AF29: =SUM(T29:AE29) -> 600000 | AS29: =SUM(AG29:AR29) -> 0 | BF29: =SUM(AT29:BE29) -> 0 | BH29: 0 | BI29: =S29-BH29 -> 0
A30: =A29+1 -> 26 | B30: A-26 | C30: 0 | F30: 0 | S30: =SUM(G30:R30) -> 0 | T30: 100000 | U30: 100000 | V30: 100000 | W30: 100000 | X30: 100000 | Y30: 100000 | Z30: 100000 | AA30: 100000 | AB30: 100000 | AC30: 100000 | AD30: 100000 | AE30: 100000 | AF30: =SUM(T30:AE30) -> 1200000 | AG30: 100000 | AH30: 100000 | AI30: 100000 | AJ30: 100000 | AK30: 100000 | AL30: 100000 | AM30: 100000 | AN30: 100000 | AO30: 100000 | AP30: 100000 | AQ30: 100000 | AR30: 100000 | AS30: =SUM(AG30:AR30) -> 1200000 | BF30: =SUM(AT30:BE30) -> 0 | BH30: 0 | BI30: =S30-BH30 -> 0
A31: =A30+1 -> 27 | B31: A-27 | C31: Muh Darsul Khafid | D31: Rumah Tinggal | E31: Dihuni sendiri | F31: 0 | S31: =SUM(G31:R31) -> 0 | T31: 100000 | U31: 100000 | V31: 100000 | W31: 100000 | X31: 100000 | Y31: 100000 | Z31: 100000 | AA31: 100000 | AB31: 100000 | AC31: 100000 | AD31: 100000 | AE31: 100000 | AF31: =SUM(T31:AE31) -> 1200000 | AG31: 100000 | AH31: 100000 | AI31: 100000 | AJ31: 100000 | AK31: 100000 | AS31: =SUM(AG31:AR31) -> 500000 | BF31: =SUM(AT31:BE31) -> 0 | BH31: 0 | BI31: =S31-BH31 -> 0
A32: =A31+1 -> 28 | B32: A-28 | C32: 0 | F32: 0 | S32: =SUM(G32:R32) -> 0 | T32: 100000 | U32: 100000 | V32: 100000 | W32: 100000 | X32: 100000 | Y32: 100000 | Z32: 100000 | AA32: 100000 | AB32: 100000 | AC32: 100000 | AD32: 100000 | AE32: 100000 | AF32: =SUM(T32:AE32) -> 1200000 | AS32: =SUM(AG32:AR32) -> 0 | BF32: =SUM(AT32:BE32) -> 0 | BH32: 0 | BI32: =S32-BH32 -> 0
A33: =A32+1 -> 29 | B33: A-29 | C33: 0 | F33: 0 | S33: =SUM(G33:R33) -> 0 | T33: 100000 | U33: 100000 | V33: 100000 | W33: 100000 | X33: 100000 | Y33: 100000 | Z33: 100000 | AA33: 100000 | AB33: 100000 | AC33: 100000 | AD33: 100000 | AE33: 100000 | AF33: =SUM(T33:AE33) -> 1200000 | AG33: 100000 | AH33: 100000 | AI33: 100000 | AJ33: 100000 | AS33: =SUM(AG33:AR33) -> 400000 | BF33: =SUM(AT33:BE33) -> 0 | BH33: 0 | BI33: =S33-BH33 -> 0
A34: =A33+1 -> 30 | B34: A-30 | C34: 0 | F34: 0 | S34: =SUM(G34:R34) -> 0 | T34: 100000 | U34: 100000 | V34: 100000 | W34: 100000 | X34: 100000 | Y34: 100000 | Z34: 100000 | AA34: 100000 | AB34: 100000 | AC34: 100000 | AD34: 100000 | AE34: 100000 | AF34: =SUM(T34:AE34) -> 1200000 | AG34: 100000 | AH34: 100000 | AI34: 100000 | AJ34: 100000 | AS34: =SUM(AG34:AR34) -> 400000 | BF34: =SUM(AT34:BE34) -> 0 | BH34: 0 | BI34: =S34-BH34 -> 0
A35: =A34+1 -> 31 | B35: A-31 | C35: 0 | F35: 0 | S35: =SUM(G35:R35) -> 0 | AF35: =SUM(T35:AE35) -> 0 | AS35: =SUM(AG35:AR35) -> 0 | BF35: =SUM(AT35:BE35) -> 0 | BH35: 0 | BI35: =S35-BH35 -> 0
A36: =A35+1 -> 32 | B36: A-32 | C36: 0 | F36: 0 | S36: =SUM(G36:R36) -> 0 | T36: 100000 | U36: 100000 | V36: 100000 | W36: 100000 | X36: 100000 | Y36: 100000 | Z36: 100000 | AA36: 100000 | AB36: 100000 | AC36: 100000 | AF36: =SUM(T36:AE36) -> 1000000 | AS36: =SUM(AG36:AR36) -> 0 | BF36: =SUM(AT36:BE36) -> 0 | BH36: 0 | BI36: =S36-BH36 -> 0
A37: =A36+1 -> 33 | B37: A-33 | C37: 0 | F37: 0 | S37: =SUM(G37:R37) -> 0 | AF37: =SUM(T37:AE37) -> 0 | AS37: =SUM(AG37:AR37) -> 0 | BF37: =SUM(AT37:BE37) -> 0 | BH37: 0 | BI37: =S37-BH37 -> 0
A38: =A37+1 -> 34 | B38: A-34 | C38: 0 | F38: 0 | S38: =SUM(G38:R38) -> 0 | T38: 100000 | U38: 100000 | V38: 100000 | W38: 100000 | X38: 100000 | Y38: 100000 | Z38: 100000 | AA38: 100000 | AB38: 100000 | AC38: 100000 | AD38: 100000 | AE38: 100000 | AF38: =SUM(T38:AE38) -> 1200000 | AG38: 100000 | AH38: 100000 | AI38: 100000 | AJ38: 100000 | AK38: 100000 | AL38: 100000 | AS38: =SUM(AG38:AR38) -> 600000 | BF38: =SUM(AT38:BE38) -> 0 | BH38: 0 | BI38: =S38-BH38 -> 0
A39: =A38+1 -> 35 | B39: A-35 | C39: 0 | F39: 0 | S39: =SUM(G39:R39) -> 0 | T39: 100000 | U39: 100000 | V39: 100000 | W39: 100000 | X39: 100000 | Y39: 100000 | Z39: 100000 | AA39: 100000 | AB39: 100000 | AC39: 100000 | AD39: 100000 | AE39: 100000 | AF39: =SUM(T39:AE39) -> 1200000 | AG39: 100000 | AH39: 100000 | AI39: 100000 | AJ39: 100000 | AK39: 100000 | AL39: 100000 | AM39: 100000 | AN39: 100000 | AO39: 100000 | AP39: 100000 | AQ39: 100000 | AR39: 100000 | AS39: =SUM(AG39:AR39) -> 1200000 | BF39: =SUM(AT39:BE39) -> 0 | BH39: 0 | BI39: =S39-BH39 -> 0
A40: =A39+1 -> 36 | B40: A-35-A | C40: 0 | F40: 0 | S40: =SUM(G40:R40) -> 0 | T40: 100000 | U40: 100000 | V40: 100000 | W40: 100000 | X40: 100000 | Y40: 100000 | Z40: 100000 | AA40: 100000 | AB40: 100000 | AC40: 100000 | AD40: 100000 | AE40: 100000 | AF40: =SUM(T40:AE40) -> 1200000 | AG40: 100000 | AH40: 100000 | AI40: 100000 | AJ40: 100000 | AS40: =SUM(AG40:AR40) -> 400000 | BF40: =SUM(AT40:BE40) -> 0
...

Sheet PVT IURAN
A3: Sum of Dr | B3: Column Labels
A4: Row Labels | B4: 1 | C4: 2 | D4: 3 | E4: 4 | F4: 5 | G4: 6 | H4: 7 | I4: 8 | J4: 9 | K4: 10 | L4: 11 | M4: 12 | N4: 0125 | O4: 0225 | P4: 0325 | Q4: 0425 | R4: 0525 | S4: 0625 | T4: 0725 | U4: 0825 | V4: 0925 | W4: 1025 | X4: 1125 | Y4: 1225 | Z4: Grand Total
A5: A-02 | B5: 100000 | C5: 100000 | D5: 100000 | E5: 100000 | F5: 100000 | Z5: 500000
A6: A-03 | B6: 100000 | C6: 100000 | D6: 100000 | Z6: 300000
A7: A-04 | B7: 100000 | C7: 100000 | D7: 100000 | E7: 100000 | F7: 100000 | Z7: 500000
A8: A-05 | B8: 100000 | C8: 100000 | D8: 100000 | E8: 100000 | Z8: 400000
A9: A-06 | B9: 100000 | C9: 100000 | D9: 100000 | E9: 100000 | F9: 100000 | G9: 100000 | H9: 100000 | I9: 100000 | J9: 100000 | K9: 100000 | L9: 100000 | M9: 100000 | Z9: 1200000
A10: A-07 | B10: 100000 | C10: 100000 | D10: 100000 | E10: 150000 | F10: 100000 | G10: 100000 | H10: 100000 | I10: 100000 | J10: 100000 | K10: 100000 | L10: 100000 | M10: 100000 | Z10: 1250000
A11: A-09 | B11: 100000 | C11: 100000 | D11: 100000 | E11: 100000 | Z11: 400000
A12: A-11 | D12: 100000 | E12: 100000 | Z12: 200000
A13: A-12 | B13: 100000 | C13: 100000 | D13: 100000 | E13: 100000 | F13: 100000 | G13: 100000 | Z13: 600000
A14: A-14 | B14: 100000 | C14: 100000 | D14: 100000 | E14: 100000 | F14: 100000 | Z14: 500000
A15: A-15 | B15: 100000 | C15: 100000 | D15: 100000 | E15: 100000 | F15: 100000 | G15: 100000 | H15: 100000 | I15: 100000 | J15: 100000 | Z15: 900000
A16: A-16 | B16: 100000 | C16: 100000 | D16: 100000 | E16: 100000 | F16: 100000 | Z16: 500000
A17: A-17 | B17: 100000 | C17: 100000 | D17: 100000 | E17: 100000 | F17: 100000 | G17: 100000 | H17: 100000 | I17: 100000 | J17: 100000 | K17: 100000 | L17: 100000 | M17: 100000 | Z17: 1200000
A18: A-19 | B18: 100000 | C18: 100000 | D18: 100000 | E18: 100000 | F18: 100000 | Z18: 500000
A19: A-20 | B19: 100000 | C19: 100000 | D19: 100000 | E19: 100000 | Z19: 400000
A20: A-22 | B20: 100000 | C20: 100000 | D20: 100000 | E20: 100000 | Z20: 400000
A21: A-23 | B21: 100000 | C21: 100000 | D21: 100000 | E21: 100000 | F21: 100000 | G21: 100000 | H21: 100000 | I21: 100000 | J21: 100000 | K21: 100000 | L21: 100000 | M21: 100000 | Z21: 1200000
A22: A-24 | B22: 100000 | C22: 100000 | D22: 100000 | E22: 100000 | Z22: 400000
A23: A-26 | B23: 100000 | C23: 100000 | D23: 100000 | E23: 100000 | F23: 100000 | G23: 100000 | H23: 100000 | I23: 100000 | J23: 100000 | K23: 100000 | L23: 100000 | M23: 100000 | Z23: 1200000
A24: A-27 | B24: 100000 | C24: 100000 | D24: 100000 | E24: 100000 | F24: 100000 | Z24: 500000
A25: A-29 | B25: 100000 | C25: 100000 | D25: 100000 | E25: 100000 | Z25: 400000
A26: A-30 | B26: 100000 | C26: 100000 | D26: 100000 | E26: 100000 | Z26: 400000
A27: A-34 | B27: 100000 | C27: 100000 | D27: 100000 | E27: 100000 | F27: 100000 | G27: 100000 | Z27: 600000
A28: A-35 | B28: 100000 | C28: 100000 | D28: 100000 | E28: 100000 | F28: 100000 | G28: 100000 | H28: 100000 | I28: 100000 | J28: 100000 | K28: 100000 | L28: 100000 | M28: 100000 | Z28: 1200000
A29: A-35A | B29: 100000 | C29: 100000 | D29: 100000 | E29: 100000 | Z29: 400000
A30: A-36 | B30: 100000 | C30: 100000 | D30: 100000 | E30: 100000 | F30: 100000 | Z30: 500000
A31: A-37 | B31: 100000 | C31: 100000 | D31: 100000 | E31: 100000 | F31: 100000 | X31: 100000 | Y31: 100000 | Z31: 700000
A32: A-38 | B32: 100000 | C32: 100000 | Z32: 200000
A33: A-39 | B33: 100000 | C33: 100000 | Z33: 200000
A34: A-40 | B34: 100000 | C34: 100000 | D34: 100000 | Z34: 300000
A35: B-01 | B35: 100000 | C35: 100000 | D35: 100000 | E35: 100000 | F35: 100000 | Z35: 500000
A36: B-02A | B36: 100000 | C36: 100000 | D36: 100000 | E36: 100000 | Z36: 400000
A37: B-02B | B37: 100000 | C37: 100000 | D37: 100000 | E37: 100000 | Z37: 400000
A38: B-03 | B38: 100000 | C38: 100000 | D38: 100000 | E38: 100000 | F38: 100000 | Z38: 500000
A39: B-04 | B39: 100000 | C39: 100000 | D39: 100000 | E39: 100000 | F39: 100000 | G39: 100000 | Z39: 600000
A40: B-06 | B40: 100000 | C40: 100000 | D40: 100000 | E40: 100000 | F40: 100000 | G40: 100000 | H40: 100000 | I40: 100000 | J40: 100000 | K40: 100000 | L40: 100000 | Z40: 1100000
A41: B-07 | B41: 100000 | C41: 100000 | D41: 100000 | E41: 100000 | Z41: 400000
A42: B-10 | B42: 100000 | C42: 100000 | D42: 100000 | E42: 100000 | F42: 100000 | G42: 100000 | Z42: 600000
...

Sheet Serah Terima
A1: SERAH TERIMA DARI PAK LUKMAN DAN TRANSAKSI PER TGL 01/05/26 JAM 10:00 WIB
A2: No | B2: Tgl | C2: Uraian | D2: Blok | E2: Masa | G2: Dr | H2: Cr | I2: Saldo
F3: Cash | I3: 14000000
A4: 1 | B4: 38807 | C4: Gaji Mas Haidir | E4: 3 | F4: Cash | H4: 944000 | I4: =I3+G4-H4 -> 13056000
A5: 2 | B5: 38807 | C5: Gaji Mas Saiful | E5: 3 | F5: Cash | H5: 1732000 | I5: =I4+G5-H5 -> 11324000
A6: 3 | B6: 38807 | C6: Gaji Rofik | E6: 3 | F6: Cash | H6: =1350000-750000 -> 600000 | I6: =I5+G6-H6 -> 10724000
A7: 4 | B7: 38807 | C7: Gaji marbot | E7: 3 | F7: Cash | H7: 750000 | I7: =I6+G7-H7 -> 9974000
A8: 5 | B8: 38807 | C8: Gaji Pak Santok | E8: 3 | F8: Cash | H8: 900000 | I8: =I7+G8-H8 -> 9074000
A9: 6 | B9: 46113 | C9: Wifi Pos | E9: 4 | F9: Cash | H9: 230000 | I9: =I8+G9-H9 -> 8844000
A10: 7 | B10: 46113 | C10: Iuran RT | E10: 4 | F10: Cash | H10: =375000*4 -> 1500000 | I10: =I9+G10-H10 -> 7344000
A11: 8 | B11: 46113 | C11: Halal Bi Halal | E11: 4 | F11: Cash | H11: 2000000 | I11: =I10+G11-H11 -> 5344000
A12: 9 | B12: 46113 | C12: Kas Bon Saiful | E12: 4 | F12: Cash | H12: 500000 | I12: =I11+G12-H12 -> 4844000
A13: 10 | B13: 46113 | C13: Gaji Mas Saiful | E13: 4 | F13: Cash | H13: 560000 | I13: =I12+G13-H13 -> 4284000
A14: 11 | B14: 46113 | C14: Gaji Mas Haidir | E14: 4 | F14: Cash | H14: 1180000 | I14: =I13+G14-H14 -> 3104000
A15: 12 | B15: 46143 | C15: Transfer masuk pak Lukman | E15: 4 | F15: Transfer | G15: 5100000 | I15: =I14+G15-H15 -> 8204000
A16: 13 | B16: 46143 | C16: Gaji marbot | E16: 4 | F16: Cash | H16: 750000 | I16: =I15+G16-H16 -> 7454000
A17: 14 | B17: 46143 | C17: Gaji Rofik | E17: 4 | F17: Cash | H17: 750000 | I17: =I16+G17-H17 -> 6704000
A18: 15 | B18: 46143 | C18: Gaji Pak Santok | E18: 4 | F18: Cash | H18: 900000 | I18: =I17+G18-H18 -> 5804000
A19: 16 | B19: 46143 | C19: iuran pak afrijal | E19: 5 | F19: Transfer | G19: 100000 | I19: =I18+G19-H19 -> 5904000
A20: 17 | B20: 46143 | C20: iuran pak ghozaimi | E20: 5 | F20: Transfer | G20: 200000 | I20: =I19+G20-H20 -> 6104000
A21: 18 | B21: 46143 | C21: iuran pak sumaryanto | E21: 5 | F21: Transfer | G21: 1320000 | I21: =I20+G21-H21 -> 7424000
A22: 19 | B22: 46143 | C22: iuran pak andrianto | E22: 5 | F22: Transfer | G22: 200000 | I22: =I21+G22-H22 -> 7624000
A23: 20 | B23: 46143 | C23: Beli ATK | E23: 5 | F23: Transfer | H23: 19000 | I23: =I22+G23-H23 -> 7605000
A24: 21 | B24: 46143 | C24: Bayar PDAM Musholla | E24: 5 | F24: Transfer | H24: 14500 | I24: =I23+G24-H24 -> 7590500
A25: 22 | B25: 46143 | C25: Bayar Listrik Musholla | E25: 5 | F25: Transfer | H25: =39648+3500 -> 43148 | I25: =I24+G25-H25 -> 7547352
A26: 23 | B26: 46143 | C26: iuran pak cahya | E26: 5 | F26: Transfer | G26: 200000 | I26: =I25+G26-H26 -> 7747352
A28: PENARIKAN TUNAI KE WARGA
A29: No | B29: Tgl | C29: Uraian | D29: Blok | E29: Masa | G29: Dr | H29: Cr | I29: Saldo
I30: 0
A31: 1 | B31: 46142 | C31: Iuran Warga | D31: B-23 | E31: 3 | F31: Cash | G31: 100000 | I31: =I30+G31-H31 -> 100000
A32: 2 | B32: 46142 | C32: Iuran Warga | D32: B-23 | E32: 4 | F32: Cash | G32: 100000 | I32: =I31+G32-H32 -> 200000
A33: 3 | B33: 46142 | C33: Iuran Warga | D33: A-02 | E33: 1 | F33: Cash | G33: 100000 | I33: =I32+G33-H33 -> 300000
A34: 4 | B34: 46142 | C34: Iuran Warga | D34: A-02 | E34: 2 | F34: Cash | G34: 100000 | I34: =I33+G34-H34 -> 400000
A35: 5 | B35: 46142 | C35: Iuran Warga | D35: A-02 | E35: 3 | F35: Cash | G35: 100000 | I35: =I34+G35-H35 -> 500000
A36: 6 | B36: 46142 | C36: Iuran Warga | D36: A-02 | E36: 4 | F36: Cash | G36: 100000 | I36: =I35+G36-H36 -> 600000
A37: 7 | B37: 46142 | C37: Iuran Warga | D37: A-22 | E37: 1 | F37: Cash | G37: 100000 | I37: =I36+G37-H37 -> 700000
A38: 8 | B38: 46142 | C38: Iuran Warga | D38: A-22 | E38: 2 | F38: Cash | G38: 100000 | I38: =I37+G38-H38 -> 800000
A39: 9 | B39: 46142 | C39: Iuran Warga | D39: A-22 | E39: 3 | F39: Cash | G39: 100000 | I39: =I38+G39-H39 -> 900000
A40: 10 | B40: 46142 | C40: Iuran Warga | D40: A-22 | E40: 4 | F40: Cash | G40: 100000 | I40: =I39+G40-H40 -> 1000000
A41: 11 | B41: 46142 | C41: Iuran Warga | D41: C-09 | E41: 1 | F41: Cash | G41: 100000 | I41: =I40+G41-H41 -> 1100000
...

Sheet JURNAL_25
A1: ='LR BLN'!A1:M1 -> Paguyuban Puri Bunga 2
A2: Laporan Kinerja Keuangan Tahun 2025
A5: JURNAL HARIAN PURI BUNGA 2 TAHUN 2025
A7: No. | B7: Tanggal | C7: Month | D7: SD | E7: MS BYR | F7: ACC | G7: ACC NAME | H7: URAIAN TRANSAKSI | I7: Blok | J7: Dr | K7: Cr | L7: Saldo | M7: Cek Saldo RK | N7: Cek Saldo Kas | O7: Selisih
A8: 1 | B8: 46023 | C8: =MONTH(B8) -> 1 | D8: 5 | G8: Saldo awal | L8: 0
A9: 1 | B9: 46137 | C9: =MONTH(B9) -> 4 | D9: 5 | E9: 1 | F9: 40 | G9: =IFERROR(VLOOKUP(F9,COA!$A$1:$K$26,2,FALSE),0) -> Penerimaan Iuran Warga | H9: Iuran Amir | I9: C-09 | J9: 100000 | L9: =L8+J9-K9 -> 100000
A10: =A9+1 -> 2 | B10: 46137 | C10: =MONTH(B10) -> 4 | D10: 5 | E10: 2 | F10: 40 | G10: =IFERROR(VLOOKUP(F10,COA!$A$1:$K$26,2,FALSE),0) -> Penerimaan Iuran Warga | H10: Iuran Amir | I10: C-09 | J10: 100000 | L10: =L9+J10-K10 -> 200000
A11: =A10+1 -> 3 | B11: 46137 | C11: =MONTH(B11) -> 4 | D11: 5 | E11: 3 | F11: 40 | G11: =IFERROR(VLOOKUP(F11,COA!$A$1:$K$26,2,FALSE),0) -> Penerimaan Iuran Warga | H11: Iuran Amir | I11: C-09 | J11: 100000 | L11: =L10+J11-K11 -> 300000
A12: =A11+1 -> 4 | B12: 46137 | C12: =MONTH(B12) -> 4 | D12: 5 | E12: 4 | F12: 40 | G12: =IFERROR(VLOOKUP(F12,COA!$A$1:$K$26,2,FALSE),0) -> Penerimaan Iuran Warga | H12: Iuran Amir | I12: C-09 | J12: 100000 | L12: =L11+J12-K12 -> 400000
A13: =A12+1 -> 5 | B13: 46137 | C13: =MONTH(B13) -> 4 | D13: 5 | E13: 5 | F13: 40 | G13: =IFERROR(VLOOKUP(F13,COA!$A$1:$K$26,2,FALSE),0) -> Penerimaan Iuran Warga | H13: Iuran Amir | I13: C-09 | J13: 100000 | L13: =L12+J13-K13 -> 500000
A14: =A13+1 -> 6 | B14: 46137 | C14: =MONTH(B14) -> 4 | D14: 5 | E14: 6 | F14: 40 | G14: =IFERROR(VLOOKUP(F14,COA!$A$1:$K$26,2,FALSE),0) -> Penerimaan Iuran Warga | H14: Iuran Amir | I14: C-09 | J14: 100000 | L14: =L13+J14-K14 -> 600000
A15: =A14+1 -> 7 | B15: 46137 | C15: =MONTH(B15) -> 4 | D15: 5 | E15: 7 | F15: 40 | G15: =IFERROR(VLOOKUP(F15,COA!$A$1:$K$26,2,FALSE),0) -> Penerimaan Iuran Warga | H15: Iuran Amir | I15: C-09 | J15: 100000 | L15: =L14+J15-K15 -> 700000
A16: =A15+1 -> 8 | B16: 46137 | C16: =MONTH(B16) -> 4 | D16: 5 | E16: 8 | F16: 40 | G16: =IFERROR(VLOOKUP(F16,COA!$A$1:$K$26,2,FALSE),0) -> Penerimaan Iuran Warga | H16: Iuran Amir | I16: C-09 | J16: 100000 | L16: =L15+J16-K16 -> 800000
A17: =A16+1 -> 9 | B17: 46137 | C17: =MONTH(B17) -> 4 | D17: 5 | E17: 9 | F17: 40 | G17: =IFERROR(VLOOKUP(F17,COA!$A$1:$K$26,2,FALSE),0) -> Penerimaan Iuran Warga | H17: Iuran Amir | I17: C-09 | J17: 100000 | L17: =L16+J17-K17 -> 900000
A18: =A17+1 -> 10 | B18: 46137 | C18: =MONTH(B18) -> 4 | D18: 5 | E18: 10 | F18: 40 | G18: =IFERROR(VLOOKUP(F18,COA!$A$1:$K$26,2,FALSE),0) -> Penerimaan Iuran Warga | H18: Iuran Amir | I18: C-09 | J18: 100000 | L18: =L17+J18-K18 -> 1000000
A19: =A18+1 -> 11 | B19: 46137 | C19: =MONTH(B19) -> 4 | D19: 5 | E19: 11 | F19: 40 | G19: =IFERROR(VLOOKUP(F19,COA!$A$1:$K$26,2,FALSE),0) -> Penerimaan Iuran Warga | H19: Iuran Amir | I19: C-09 | J19: 100000 | L19: =L18+J19-K19 -> 1100000
A20: =A19+1 -> 12 | B20: 46137 | C20: =MONTH(B20) -> 4 | D20: 5 | E20: 12 | F20: 40 | G20: =IFERROR(VLOOKUP(F20,COA!$A$1:$K$26,2,FALSE),0) -> Penerimaan Iuran Warga | H20: Iuran Amir | I20: C-09 | J20: 100000 | L20: =L19+J20-K20 -> 1200000
A21: =A20+1 -> 13 | B21: 46143 | C21: =MONTH(B21) -> 5 | D21: 5 | E21: 11 | F21: 40 | G21: =IFERROR(VLOOKUP(F21,COA!$A$1:$K$26,2,FALSE),0) -> Penerimaan Iuran Warga | I21: A-37 | J21: 100000 | L21: =L20+J21-K21 -> 1300000
A22: =A21+1 -> 14 | B22: 46143 | C22: =MONTH(B22) -> 5 | D22: 5 | E22: 12 | F22: 40 | G22: =IFERROR(VLOOKUP(F22,COA!$A$1:$K$26,2,FALSE),0) -> Penerimaan Iuran Warga | I22: A-37 | J22: 100000 | L22: =L21+J22-K22 -> 1400000
A23: =A22+1 -> 15 | B23: 46144 | C23: =MONTH(B23) -> 5 | D23: 5 | E23: 9 | F23: 40 | G23: =IFERROR(VLOOKUP(F23,COA!$A$1:$K$26,2,FALSE),0) -> Penerimaan Iuran Warga | H23: Iuran Mahameru Eki | I23: C-08 | J23: 100000 | L23: =L22+J23-K23 -> 1500000
A24: =A23+1 -> 16 | B24: 46144 | C24: =MONTH(B24) -> 5 | D24: 5 | E24: 10 | F24: 40 | G24: =IFERROR(VLOOKUP(F24,COA!$A$1:$K$26,2,FALSE),0) -> Penerimaan Iuran Warga | H24: Iuran Mahameru Eki | I24: C-08 | J24: 100000 | L24: =L23+J24-K24 -> 1600000
A25: =A24+1 -> 17 | B25: 46144 | C25: =MONTH(B25) -> 5 | D25: 5 | E25: 11 | F25: 40 | G25: =IFERROR(VLOOKUP(F25,COA!$A$1:$K$26,2,FALSE),0) -> Penerimaan Iuran Warga | H25: Iuran Mahameru Eki | I25: C-08 | J25: 100000 | L25: =L24+J25-K25 -> 1700000
A26: =A25+1 -> 18 | B26: 46144 | C26: =MONTH(B26) -> 5 | D26: 5 | E26: 12 | F26: 40 | G26: =IFERROR(VLOOKUP(F26,COA!$A$1:$K$26,2,FALSE),0) -> Penerimaan Iuran Warga | H26: Iuran Mahameru Eki | I26: C-08 | J26: 100000 | L26: =L25+J26-K26 -> 1800000
A27: =A26+1 -> 19 | C27: =MONTH(B27) -> 1 | D27: 5 | G27: =IFERROR(VLOOKUP(F27,COA!$A$1:$K$26,2,FALSE),0) -> 0 | L27: =L26+J27-K27 -> 1800000
A28: =A27+1 -> 20 | C28: =MONTH(B28) -> 1 | D28: 5 | G28: =IFERROR(VLOOKUP(F28,COA!$A$1:$K$26,2,FALSE),0) -> 0 | L28: =L27+J28-K28 -> 1800000
A29: =A28+1 -> 21 | C29: =MONTH(B29) -> 1 | D29: 5 | G29: =IFERROR(VLOOKUP(F29,COA!$A$1:$K$26,2,FALSE),0) -> 0 | L29: =L28+J29-K29 -> 1800000
A30: =A29+1 -> 22 | C30: =MONTH(B30) -> 1 | D30: 5 | G30: =IFERROR(VLOOKUP(F30,COA!$A$1:$K$26,2,FALSE),0) -> 0 | L30: =L29+J30-K30 -> 1800000
A31: =A30+1 -> 23 | C31: =MONTH(B31) -> 1 | D31: 5 | G31: =IFERROR(VLOOKUP(F31,COA!$A$1:$K$26,2,FALSE),0) -> 0 | L31: =L30+J31-K31 -> 1800000
A32: =A31+1 -> 24 | C32: =MONTH(B32) -> 1 | D32: 5 | G32: =IFERROR(VLOOKUP(F32,COA!$A$1:$K$26,2,FALSE),0) -> 0 | L32: =L31+J32-K32 -> 1800000
A33: =A32+1 -> 25 | C33: =MONTH(B33) -> 1 | D33: 5 | G33: =IFERROR(VLOOKUP(F33,COA!$A$1:$K$26,2,FALSE),0) -> 0 | L33: =L32+J33-K33 -> 1800000
A34: =A33+1 -> 26 | C34: =MONTH(B34) -> 1 | D34: 5 | G34: =IFERROR(VLOOKUP(F34,COA!$A$1:$K$26,2,FALSE),0) -> 0 | L34: =L33+J34-K34 -> 1800000
A35: =A34+1 -> 27 | C35: =MONTH(B35) -> 1 | D35: 5 | G35: =IFERROR(VLOOKUP(F35,COA!$A$1:$K$26,2,FALSE),0) -> 0 | L35: =L34+J35-K35 -> 1800000
A36: =A35+1 -> 28 | C36: =MONTH(B36) -> 1 | D36: 5 | G36: =IFERROR(VLOOKUP(F36,COA!$A$1:$K$26,2,FALSE),0) -> 0 | L36: =L35+J36-K36 -> 1800000
A37: =A36+1 -> 29 | C37: =MONTH(B37) -> 1 | D37: 5 | G37: =IFERROR(VLOOKUP(F37,COA!$A$1:$K$26,2,FALSE),0) -> 0 | L37: =L36+J37-K37 -> 1800000
A38: =A37+1 -> 30 | C38: =MONTH(B38) -> 1 | D38: 5 | G38: =IFERROR(VLOOKUP(F38,COA!$A$1:$K$26,2,FALSE),0) -> 0 | L38: =L37+J38-K38 -> 1800000
... A358: =A357+1 -> 350 | C358: =MONTH(B358) -> 1 | D358: 5 | G358: =IFERROR(VLOOKUP(F358,COA!$A$1:$K$26,2,FALSE),0) -> 0 | L358: =L357+J358-K358 -> 1800000
A359: =A358+1 -> 351 | C359: =MONTH(B359) -> 1 | D359: 5 | G359: =IFERROR(VLOOKUP(F359,COA!$A$1:$K$26,2,FALSE),0) -> 0 | L359: =L358+J359-K359 -> 1800000 | M359: 12535852 | N359: 304000 | O359: =L359-M359-N359 -> -11039852
A360: =A359+1 -> 352 | C360: =MONTH(B360) -> 1 | D360: 5 | G360: =IFERROR(VLOOKUP(F360,COA!$A$1:$K$26,2,FALSE),0) -> 0 | L360: =L359+J360-K360 -> 1800000
A361: =A360+1 -> 353 | C361: =MONTH(B361) -> 1 | D361: 5 | G361: =IFERROR(VLOOKUP(F361,COA!$A$1:$K$26,2,FALSE),0) -> 0 | L361: =L360+J361-K361 -> 1800000
A362: =A361+1 -> 354 | C362: =MONTH(B362) -> 1 | D362: 5 | G362: =IFERROR(VLOOKUP(F362,COA!$A$1:$K$26,2,FALSE),0) -> 0 | L362: =L361+J362-K362 -> 1800000
...

Sheet KAS KECIL
A1: ='LR BLN'!A1:M1 -> Paguyuban Puri Bunga 2
A2: Laporan Kinerja Keuangan Tahun 2025
A5: JURNAL HARIAN PURI BUNGA 2 TAHUN 2025
A7: No. | B7: Tanggal | C7: Month | D7: SD | E7: MS BYR | F7: ACC | G7: ACC NAME | H7: URAIAN TRANSAKSI | I7: Blok | J7: Dr | K7: Cr | L7: Saldo | M7: Cek Saldo RK | N7: Cek Saldo Kas | O7: Selisih
A8: 1 | B8: 46023 | C8: =MONTH(B8) -> 1 | D8: 5 | G8: Saldo awal | L8: 0
A9: 1 | B9: 46144 | C9: =MONTH(B9) -> 5 | D9: 5 | E9: 1 | F9: 11 | G9: =IFERROR(VLOOKUP(F9,COA!$A$1:$K$26,2,FALSE),0) -> Kas Kecil | H9: Kas kecil awal | J9: 304000 | L9: =L8+J9-K9 -> 304000
A10: =A9+1 -> 2 | B10: 46149 | C10: =MONTH(B10) -> 5 | D10: 5 | E10: 1 | F10: 11 | G10: =IFERROR(VLOOKUP(F10,COA!$A$1:$K$26,2,FALSE),0) -> Kas Kecil | H10: Pengambilan tunai untuk kas kecil | J10: 200000 | L10: =L9+J10-K10 -> 504000
A11: =A10+1 -> 3 | C11: =MONTH(B11) -> 1 | D11: 5 | G11: =IFERROR(VLOOKUP(F11,COA!$A$1:$K$26,2,FALSE),0) -> 0 | L11: =L10+J11-K11 -> 504000
A12: =A11+1 -> 4 | C12: =MONTH(B12) -> 1 | D12: 5 | G12: =IFERROR(VLOOKUP(F12,COA!$A$1:$K$26,2,FALSE),0) -> 0 | L12: =L11+J12-K12 -> 504000
A13: =A12+1 -> 5 | C13: =MONTH(B13) -> 1 | D13: 5 | G13: =IFERROR(VLOOKUP(F13,COA!$A$1:$K$26,2,FALSE),0) -> 0 | L13: =L12+J13-K13 -> 504000
A14: =A13+1 -> 6 | C14: =MONTH(B14) -> 1 | D14: 5 | G14: =IFERROR(VLOOKUP(F14,COA!$A$1:$K$26,2,FALSE),0) -> 0 | L14: =L13+J14-K14 -> 504000
A15: =A14+1 -> 7 | C15: =MONTH(B15) -> 1 | D15: 5 | G15: =IFERROR(VLOOKUP(F15,COA!$A$1:$K$26,2,FALSE),0) -> 0 | L15: =L14+J15-K15 -> 504000
A16: =A15+1 -> 8 | C16: =MONTH(B16) -> 1 | D16: 5 | G16: =IFERROR(VLOOKUP(F16,COA!$A$1:$K$26,2,FALSE),0) -> 0 | L16: =L15+J16-K16 -> 504000
A17: =A16+1 -> 9 | C17: =MONTH(B17) -> 1 | D17: 5 | G17: =IFERROR(VLOOKUP(F17,COA!$A$1:$K$26,2,FALSE),0) -> 0 | L17: =L16+J17-K17 -> 504000
A18: =A17+1 -> 10 | C18: =MONTH(B18) -> 1 | D18: 5 | G18: =IFERROR(VLOOKUP(F18,COA!$A$1:$K$26,2,FALSE),0) -> 0 | L18: =L17+J18-K18 -> 504000
A19: =A18+1 -> 11 | C19: =MONTH(B19) -> 1 | D19: 5 | G19: =IFERROR(VLOOKUP(F19,COA!$A$1:$K$26,2,FALSE),0) -> 0 | L19: =L18+J19-K19 -> 504000
A20: =A19+1 -> 12 | C20: =MONTH(B20) -> 1 | D20: 5 | G20: =IFERROR(VLOOKUP(F20,COA!$A$1:$K$26,2,FALSE),0) -> 0 | L20: =L19+J20-K20 -> 504000
A21: =A20+1 -> 13 | C21: =MONTH(B21) -> 1 | D21: 5 | G21: =IFERROR(VLOOKUP(F21,COA!$A$1:$K$26,2,FALSE),0) -> 0 | L21: =L20+J21-K21 -> 504000
A22: =A21+1 -> 14 | C22: =MONTH(B22) -> 1 | D22: 5 | G22: =IFERROR(VLOOKUP(F22,COA!$A$1:$K$26,2,FALSE),0) -> 0 | L22: =L21+J22-K22 -> 504000
... A358: =A357+1 -> 350 | C358: =MONTH(B358) -> 1 | D358: 5 | G358: =IFERROR(VLOOKUP(F358,COA!$A$1:$K$26,2,FALSE),0) -> 0 | L358: =L357+J358-K358 -> 504000
A359: =A358+1 -> 351 | C359: =MONTH(B359) -> 1 | D359: 5 | G359: =IFERROR(VLOOKUP(F359,COA!$A$1:$K$26,2,FALSE),0) -> 0 | L359: =L358+J359-K359 -> 504000 | M359: 12535852 | N359: 304000 | O359: =L359-M359-N359 -> -12335852
A360: =A359+1 -> 352 | C360: =MONTH(B360) -> 1 | D360: 5 | G360: =IFERROR(VLOOKUP(F360,COA!$A$1:$K$26,2,FALSE),0) -> 0 | L360: =L359+J360-K360 -> 504000
A361: =A360+1 -> 353 | C361: =MONTH(B361) -> 1 | D361: 5 | G361: =IFERROR(VLOOKUP(F361,COA!$A$1:$K$26,2,FALSE),0) -> 0 | L361: =L360+J361-K361 -> 504000
A362: =A361+1 -> 354 | C362: =MONTH(B362) -> 1 | D362: 5 | G362: =IFERROR(VLOOKUP(F362,COA!$A$1:$K$26,2,FALSE),0) -> 0 | L362: =L361+J362-K362 -> 504000
A363: =A362+1 -> 355 | C363: =MONTH(B363) -> 1 | D363: 5 | G363: =IFERROR(VLOOKUP(F363,COA!$A$1:$K$26,2,FALSE),0) -> 0 | L363: =L362+J363-K363 -> 504000
A364: =A363+1 -> 356 | C364: =MONTH(B364) -> 1 | D364: 5 | G364: =IFERROR(VLOOKUP(F364,COA!$A$1:$K$26,2,FALSE),0) -> 0 | L364: =L363+J364-K364 -> 504000
A365: =A364+1 -> 357 | C365: =MONTH(B365) -> 1 | D365: 5 | G365: =IFERROR(VLOOKUP(F365,COA!$A$1:$K$26,2,FALSE),0) -> 0 | L365: =L364+J365-K365 -> 504000
A366: =A365+1 -> 358 | C366: =MONTH(B366) -> 1 | D366: 5 | G366: =IFERROR(VLOOKUP(F366,COA!$A$1:$K$26,2,FALSE),0) -> 0 | L366: =L365+J366-K366 -> 504000
A367: =A366+1 -> 359 | C367: =MONTH(B367) -> 1 | D367: 5 | G367: =IFERROR(VLOOKUP(F367,COA!$A$1:$K$26,2,FALSE),0) -> 0 | L367: =L366+J367-K367 -> 504000
A368: =A367+1 -> 360 | C368: =MONTH(B368) -> 1 | D368: 5 | G368: =IFERROR(VLOOKUP(F368,COA!$A$1:$K$26,2,FALSE),0) -> 0 | L368: =L367+J368-K368 -> 504000
A369: =A368+1 -> 361 | C369: =MONTH(B369) -> 1 | D369: 5 | G369: =IFERROR(VLOOKUP(F369,COA!$A$1:$K$26,2,FALSE),0) -> 0 | L369: =L368+J369-K369 -> 504000
A370: =A369+1 -> 362 | C370: =MONTH(B370) -> 1 | D370: 5 | G370: =IFERROR(VLOOKUP(F370,COA!$A$1:$K$26,2,FALSE),0) -> 0 | L370: =L369+J370-K370 -> 504000
A371: =A370+1 -> 363 | C371: =MONTH(B371) -> 1 | D371: 5 | G371: =IFERROR(VLOOKUP(F371,COA!$A$1:$K$26,2,FALSE),0) -> 0 | L371: =L370+J371-K371 -> 504000
... A408: =A407+1 -> 400 | C408: =MONTH(B408) -> 1 | D408: 5 | G408: =IFERROR(VLOOKUP(F408,COA!$A$1:$K$26,2,FALSE),0) -> 0 | L408: =L407+J408-K408 -> 504000
A409: =A408+1 -> 401 | C409: =MONTH(B409) -> 1 | G409: =IFERROR(VLOOKUP(F409,COA!$A$1:$K$26,2,FALSE),0) -> 0 | L409: =L408+J409-K409 -> 504000
A410: =A409+1 -> 402 | C410: =MONTH(B410) -> 1 | G410: =IFERROR(VLOOKUP(F410,COA!$A$1:$K$26,2,FALSE),0) -> 0 | L410: =L409+J410-K410 -> 504000
A411: =A410+1 -> 403 | C411: =MONTH(B411) -> 1 | G411: =IFERROR(VLOOKUP(F411,COA!$A$1:$K$26,2,FALSE),0) -> 0 | L411: =L410+J411-K411 -> 504000
A412: =A411+1 -> 404 | C412: =MONTH(B412) -> 1 | G412: =IFERROR(VLOOKUP(F412,COA!$A$1:$K$26,2,FALSE),0) -> 0 | L412: =L411+J412-K412 -> 504000
A413: =A412+1 -> 405 | C413: =MONTH(B413) -> 1 | G413: =IFERROR(VLOOKUP(F413,COA!$A$1:$K$26,2,FALSE),0) -> 0 | L413: =L412+J413-K413 -> 504000
A414: =A413+1 -> 406 | C414: =MONTH(B414) -> 1 | G414: =IFERROR(VLOOKUP(F414,COA!$A$1:$K$26,2,FALSE),0) -> 0 | L414: =L413+J414-K414 -> 504000
...

Sheet JURNAL_26
A1: ='LR BLN'!A1:M1 -> Paguyuban Puri Bunga 2
A2: ='LR BLN'!A2:M2 -> Laporan Kinerja Keuangan Tahun 2026
A5: JURNAL HARIAN PURI BUNGA 2 TAHUN 2026
A7: No. | B7: Tanggal | C7: Month | D7: SD | E7: MS BYR | F7: ACC | G7: ACC NAME | H7: URAIAN TRANSAKSI | I7: Blok | J7: Dr | K7: Cr | L7: Saldo | M7: Cek Saldo RK | N7: Cek Saldo Kas | O7: Selisih
A8: 1 | B8: 46023 | C8: =MONTH(B8) -> 1 | D8: 5 | G8: Saldo awal | L8: =8450500-190000 -> 8260500
A9: 1 | B9: 46023 | C9: =MONTH(B9) -> 1 | D9: 5 | E9: 1 | F9: 40 | G9: =IFERROR(VLOOKUP(F9,COA!$A$1:$K$26,2,FALSE),0) -> Penerimaan Iuran Warga | H9: Iuran Pak Kafid | I9: A-27 | J9: 100000 | L9: =L8+J9-K9 -> 8360500
A10: =A9+1 -> 2 | B10: 46023 | C10: =MONTH(B10) -> 1 | D10: 5 | E10: 1 | F10: 40 | G10: =IFERROR(VLOOKUP(F10,COA!$A$1:$K$26,2,FALSE),0) -> Penerimaan Iuran Warga | H10: Iuran Pak Afrijal | I10: B-11B | J10: 100000 | L10: =L9+J10-K10 -> 8460500
A11: =A10+1 -> 3 | B11: 46023 | C11: =MONTH(B11) -> 1 | D11: 5 | E11: 1 | F11: 40 | G11: =IFERROR(VLOOKUP(F11,COA!$A$1:$K$26,2,FALSE),0) -> Penerimaan Iuran Warga | I11: A-14 | J11: 100000 | L11: =L10+J11-K11 -> 8560500
A12: =A11+1 -> 4 | B12: 46023 | C12: =MONTH(B12) -> 1 | D12: 5 | E12: 1 | F12: 40 | G12: =IFERROR(VLOOKUP(F12,COA!$A$1:$K$26,2,FALSE),0) -> Penerimaan Iuran Warga | I12: A-16 | J12: 100000 | L12: =L11+J12-K12 -> 8660500
A13: =A12+1 -> 5 | B13: 46026 | C13: =MONTH(B13) -> 1 | D13: 5 | E13: 1 | F13: 40 | G13: =IFERROR(VLOOKUP(F13,COA!$A$1:$K$26,2,FALSE),0) -> Penerimaan Iuran Warga | I13: D-01 | J13: 100000 | L13: =L12+J13-K13 -> 8760500
A14: =A13+1 -> 6 | B14: 46026 | C14: =MONTH(B14) -> 1 | D14: 5 | E14: 2 | F14: 40 | G14: =IFERROR(VLOOKUP(F14,COA!$A$1:$K$26,2,FALSE),0) -> Penerimaan Iuran Warga | I14: D-01 | J14: 100000 | L14: =L13+J14-K14 -> 8860500
A15: =A14+1 -> 7 | B15: 46026 | C15: =MONTH(B15) -> 1 | D15: 5 | E15: 3 | F15: 40 | G15: =IFERROR(VLOOKUP(F15,COA!$A$1:$K$26,2,FALSE),0) -> Penerimaan Iuran Warga | I15: D-01 | J15: 100000 | L15: =L14+J15-K15 -> 8960500
A16: =A15+1 -> 8 | B16: 46026 | C16: =MONTH(B16) -> 1 | D16: 5 | E16: 4 | F16: 40 | G16: =IFERROR(VLOOKUP(F16,COA!$A$1:$K$26,2,FALSE),0) -> Penerimaan Iuran Warga | I16: D-01 | J16: 100000 | L16: =L15+J16-K16 -> 9060500
A17: =A16+1 -> 9 | B17: 46026 | C17: =MONTH(B17) -> 1 | D17: 5 | E17: 5 | F17: 40 | G17: =IFERROR(VLOOKUP(F17,COA!$A$1:$K$26,2,FALSE),0) -> Penerimaan Iuran Warga | I17: D-01 | J17: 100000 | L17: =L16+J17-K17 -> 9160500
A18: =A17+1 -> 10 | B18: 46026 | C18: =MONTH(B18) -> 1 | D18: 5 | E18: 6 | F18: 20 | G18: =IFERROR(VLOOKUP(F18,COA!$A$1:$K$26,2,FALSE),0) -> Iuran Warga Diterima di muka | I18: D-01 | J18: 100000 | L18: =L17+J18-K18 -> 9260500
A19: =A18+1 -> 11 | B19: 46026 | C19: =MONTH(B19) -> 1 | D19: 5 | E19: 7 | F19: 20 | G19: =IFERROR(VLOOKUP(F19,COA!$A$1:$K$26,2,FALSE),0) -> Iuran Warga Diterima di muka | I19: D-01 | J19: 100000 | L19: =L18+J19-K19 -> 9360500
A20: =A19+1 -> 12 | B20: 46026 | C20: =MONTH(B20) -> 1 | D20: 5 | E20: 8 | F20: 20 | G20: =IFERROR(VLOOKUP(F20,COA!$A$1:$K$26,2,FALSE),0) -> Iuran Warga Diterima di muka | I20: D-01 | J20: 100000 | L20: =L19+J20-K20 -> 9460500
A21: =A20+1 -> 13 | B21: 46026 | C21: =MONTH(B21) -> 1 | D21: 5 | E21: 9 | F21: 20 | G21: =IFERROR(VLOOKUP(F21,COA!$A$1:$K$26,2,FALSE),0) -> Iuran Warga Diterima di muka | I21: D-01 | J21: 100000 | L21: =L20+J21-K21 -> 9560500
A22: =A21+1 -> 14 | B22: 46026 | C22: =MONTH(B22) -> 1 | D22: 5 | E22: 10 | F22: 20 | G22: =IFERROR(VLOOKUP(F22,COA!$A$1:$K$26,2,FALSE),0) -> Iuran Warga Diterima di muka | I22: D-01 | J22: 100000 | L22: =L21+J22-K22 -> 9660500
... A56: =A55+1 -> 48 | B56: 46053 | C56: =MONTH(B56) -> 1 | D56: 5 | E56: 1 | F56: 40 | G56: =IFERROR(VLOOKUP(F56,COA!$A$1:$K$26,2,FALSE),0) -> Penerimaan Iuran Warga | I56: A-30 | J56: 100000 | L56: =L55+J56-K56 -> 13215500
A57: =A56+1 -> 49 | B57: 46053 | C57: =MONTH(B57) -> 1 | D57: 5 | E57: 1 | F57: 50 | G57: =IFERROR(VLOOKUP(F57,COA!$A$1:$K$26,2,FALSE),0) -> Biaya Gaji Satpam | H57: Gaji Mas Haidir | K57: =1115500+500000 -> 1615500 | L57: =L56+J57-K57 -> 11600000
A58: =A57+1 -> 50 | B58: 46053 | C58: =MONTH(B58) -> 1 | D58: 5 | E58: 1 | F58: 50 | G58: =IFERROR(VLOOKUP(F58,COA!$A$1:$K$26,2,FALSE),0) -> Biaya Gaji Satpam | H58: Gaji Mas Saiful | K58: =716000+500000 -> 1216000 | L58: =L57+J58-K58 -> 10384000
A59: =A58+1 -> 51 | B59: 46053 | C59: =MONTH(B59) -> 1 | D59: 5 | E59: 1 | F59: 50 | G59: =IFERROR(VLOOKUP(F59,COA!$A$1:$K$26,2,FALSE),0) -> Biaya Gaji Satpam | H59: Gaji Samsah | K59: =189000+500000 -> 689000 | L59: =L58+J59-K59 -> 9695000
A60: =A59+1 -> 52 | B60: 46053 | C60: =MONTH(B60) -> 1 | D60: 5 | E60: 1 | F60: 51 | G60: =IFERROR(VLOOKUP(F60,COA!$A$1:$K$26,2,FALSE),0) -> Biaya Gaji Sampah | H60: Gaji Pak Santok | K60: 850000 | L60: =L59+J60-K60 -> 8845000
A61: =A60+1 -> 53 | B61: 46053 | C61: =MONTH(B61) -> 1 | D61: 5 | E61: 1 | F61: 52 | G61: =IFERROR(VLOOKUP(F61,COA!$A$1:$K$26,2,FALSE),0) -> Biaya Gaji Marbot | H61: Gaji Rofik | K61: 750000 | L61: =L60+J61-K61 -> 8095000
A62: =A61+1 -> 54 | B62: 46053 | C62: =MONTH(B62) -> 1 | D62: 5 | E62: 2 | F62: 40 | G62: =IFERROR(VLOOKUP(F62,COA!$A$1:$K$26,2,FALSE),0) -> Penerimaan Iuran Warga | I62: A-34 | J62: 100000 | L62: =L61+J62-K62 -> 8195000
A63: =A62+1 -> 55 | B63: 46054 | C63: =MONTH(B63) -> 2 | D63: 5 | E63: 1 | F63: 40 | G63: =IFERROR(VLOOKUP(F63,COA!$A$1:$K$26,2,FALSE),0) -> Penerimaan Iuran Warga | I63: B-11 | J63: 100000 | L63: =L62+J63-K63 -> 8295000
A64: =A63+1 -> 56 | B64: 46054 | C64: =MONTH(B64) -> 2 | D64: 5 | E64: 2 | F64: 40 | G64: =IFERROR(VLOOKUP(F64,COA!$A$1:$K$26,2,FALSE),0) -> Penerimaan Iuran Warga | I64: B-11 | J64: 100000 | L64: =L63+J64-K64 -> 8395000
A65: =A64+1 -> 57 | B65: 46054 | C65: =MONTH(B65) -> 2 | D65: 5 | E65: 3 | F65: 40 | G65: =IFERROR(VLOOKUP(F65,COA!$A$1:$K$26,2,FALSE),0) -> Penerimaan Iuran Warga | I65: B-11 | J65: 100000 | L65: =L64+J65-K65 -> 8495000
A66: =A65+1 -> 58 | B66: 46054 | C66: =MONTH(B66) -> 2 | D66: 5 | E66: 2 | F66: 40 | G66: =IFERROR(VLOOKUP(F66,COA!$A$1:$K$26,2,FALSE),0) -> Penerimaan Iuran Warga | H66: Iuran Pak Afrijal | I66: B-11B | J66: 100000 | L66: =L65+J66-K66 -> 8595000
A67: =A66+1 -> 59 | B67: 46054 | C67: =MONTH(B67) -> 2 | D67: 5 | E67: 2 | F67: 40 | G67: =IFERROR(VLOOKUP(F67,COA!$A$1:$K$26,2,FALSE),0) -> Penerimaan Iuran Warga | I67: A-14 | J67: 100000 | L67: =L66+J67-K67 -> 8695000
A68: =A67+1 -> 60 | B68: 46055 | C68: =MONTH(B68) -> 2 | D68: 5 | E68: 2 | F68: 40 | G68: =IFERROR(VLOOKUP(F68,COA!$A$1:$K$26,2,FALSE),0) -> Penerimaan Iuran Warga | H68: Iuran Pak Kafid | I68: A-27 | J68: 100000 | L68: =L67+J68-K68 -> 8795000
A69: =A68+1 -> 61 | B69: 46055 | C69: =MONTH(B69) -> 2 | D69: 5 | E69: 1 | F69: 40 | G69: =IFERROR(VLOOKUP(F69,COA!$A$1:$K$26,2,FALSE),0) -> Penerimaan Iuran Warga | I69: A-06 | J69: 100000 | L69: =L68+J69-K69 -> 8895000
A70: =A69+1 -> 62 | B70: 46055 | C70: =MONTH(B70) -> 2 | D70: 5 | E70: 2 | F70: 40 | G70: =IFERROR(VLOOKUP(F70,COA!$A$1:$K$26,2,FALSE),0) -> Penerimaan Iuran Warga | I70: A-06 | J70: 100000 | L70: =L69+J70-K70 -> 8995000
A71: =A70+1 -> 63 | B71: 46055 | C71: =MONTH(B71) -> 2 | D71: 5 | E71: 3 | F71: 40 | G71: =IFERROR(VLOOKUP(F71,COA!$A$1:$K$26,2,FALSE),0) -> Penerimaan Iuran Warga | I71: A-06 | J71: 100000 | L71: =L70+J71-K71 -> 9095000
A72: =A71+1 -> 64 | B72: 46055 | C72: =MONTH(B72) -> 2 | D72: 5 | E72: 4 | F72: 40 | G72: =IFERROR(VLOOKUP(F72,COA!$A$1:$K$26,2,FALSE),0) -> Penerimaan Iuran Warga | I72: A-06 | J72: 100000 | L72: =L71+J72-K72 -> 9195000
A73: =A72+1 -> 65 | B73: 46055 | C73: =MONTH(B73) -> 2 | D73: 5 | E73: 5 | F73: 40 | G73: =IFERROR(VLOOKUP(F73,COA!$A$1:$K$26,2,FALSE),0) -> Penerimaan Iuran Warga | I73: A-06 | J73: 100000 | L73: =L72+J73-K73 -> 9295000
A74: =A73+1 -> 66 | B74: 46055 | C74: =MONTH(B74) -> 2 | D74: 5 | E74: 6 | F74: 20 | G74: =IFERROR(VLOOKUP(F74,COA!$A$1:$K$26,2,FALSE),0) -> Iuran Warga Diterima di muka | I74: A-06 | J74: 100000 | L74: =L73+J74-K74 -> 9395000
A75: =A74+1 -> 67 | B75: 46055 | C75: =MONTH(B75) -> 2 | D75: 5 | E75: 7 | F75: 20 | G75: =IFERROR(VLOOKUP(F75,COA!$A$1:$K$26,2,FALSE),0) -> Iuran Warga Diterima di muka | I75: A-06 | J75: 100000 | L75: =L74+J75-K75 -> 9495000
A76: =A75+1 -> 68 | B76: 46055 | C76: =MONTH(B76) -> 2 | D76: 5 | E76: 8 | F76: 20 | G76: =IFERROR(VLOOKUP(F76,COA!$A$1:$K$26,2,FALSE),0) -> Iuran Warga Diterima di muka | I76: A-06 | J76: 100000 | L76: =L75+J76-K76 -> 9595000
...

Sheet COA
A1: 10 | B1: Kas dan Bank
A2: 11 | B2: Kas Kecil
A3: 12 | B3: Piutang Pembayaran Gaji
A4: 13 | B4: Piutang Lain-Lain
A5: 20 | B5: Iuran Warga Diterima di muka
A6: 21 | B6: Hutang lain-Lain
A7: 40 | B7: Penerimaan Iuran Warga
A8: 41 | B8: Penerimaan Lain-Lain
A9: 50 | B9: Biaya Gaji Satpam
A10: 51 | B10: Biaya Gaji Sampah
A11: 52 | B11: Biaya Gaji Marbot
A12: 53 | B12: Biaya THR
... A20: 61 | B20: Biaya Lain-Lain

Sheet LR BLN
A1: Paguyuban Puri Bunga 2 | N1: 5 | P1: 1 | Q1: JANUARI | S1: -965500 | T1: √
A2: Laporan Kinerja Keuangan Tahun 2026 | P2: 2 | Q2: FEBRUARI | S2: 663000
A3: ="PERIODE "&VLOOKUP(N1,P1:Q12,2,FALSE) -> PERIODE MEI | P3: 3 | Q3: MARET | S3: -6385000 | T3: √
A4: ="Bulan "&VLOOKUP(N1,P1:Q12,2,FALSE) -> Bulan MEI | P4: 4 | Q4: APRIL | S4: 4680000 | T4: √
A5: Penerimaan | P5: 5 | Q5: MEI | S5: =L29 -> 373700 | T5: √
A6: 40 | B6: Penerimaan Iuran Warga | J6: =SUMIFS(JURNAL_26!$J$9:$J$1764,JURNAL_26!$C$9:$C$1764,'LR BLN'!$N$1,JURNAL_26!$G$9:$G$1764,'LR BLN'!B6) -> 6310000 | P6: 6 | Q6: JUNI | T6: √
A7: 41 | B7: Penerimaan Lain-Lain | J7: =SUMIFS(JURNAL_26!$J$9:$J$1764,JURNAL_26!$C$9:$C$1764,'LR BLN'!$N$1,JURNAL_26!$G$9:$G$1764,'LR BLN'!B7) -> 100000 | P7: 7 | Q7: JULI | T7: √
J8: =SUMIFS(JURNAL_26!$J$9:$J$1764,JURNAL_26!$C$9:$C$1764,'LR BLN'!$N$1,JURNAL_26!$G$9:$G$1764,'LR BLN'!B8) -> 0 | P8: 8 | Q8: AGUSTUS | T8: √
J9: =SUMIFS(JURNAL_26!$J$9:$J$1764,JURNAL_26!$C$9:$C$1764,'LR BLN'!$N$1,JURNAL_26!$G$9:$G$1764,'LR BLN'!B9) -> 0 | P9: 9 | Q9: SEPTEMBER | T9: √
L10: =SUM(J6:K9) -> 6410000 | P10: 10 | Q10: OKTOBER | T10: √
P11: 11 | Q11: NOPEMBER | T11: √
A12: Pengeluaran | P12: 12 | Q12: DESEMBER
A13: 50 | B13: Biaya Gaji Satpam | J13: =SUMIFS(JURNAL_26!$K$9:$K$1764,JURNAL_26!$C$9:$C$1764,'LR BLN'!$N$1,JURNAL_26!$G$9:$G$1764,'LR BLN'!B13) -> 3030000 | S13: =SUM(S1:S12) -> -1633800
A14: 51 | B14: Biaya Gaji Sampah | J14: =SUMIFS(JURNAL_26!$K$9:$K$1764,JURNAL_26!$C$9:$C$1764,'LR BLN'!$N$1,JURNAL_26!$G$9:$G$1764,'LR BLN'!B14) -> 900000
A15: 52 | B15: Biaya Gaji Marbot | J15: =SUMIFS(JURNAL_26!$K$9:$K$1764,JURNAL_26!$C$9:$C$1764,'LR BLN'!$N$1,JURNAL_26!$G$9:$G$1764,'LR BLN'!B15) -> 750000
A16: 53 | B16: Biaya THR | J16: =SUMIFS(JURNAL_26!$K$9:$K$1764,JURNAL_26!$C$9:$C$1764,'LR BLN'!$N$1,JURNAL_26!$G$9:$G$1764,'LR BLN'!B16) -> 0
A17: 54 | B17: Biaya Listrik | J17: =SUMIFS(JURNAL_26!$K$9:$K$1764,JURNAL_26!$C$9:$C$1764,'LR BLN'!$N$1,JURNAL_26!$G$9:$G$1764,'LR BLN'!B17) -> 39648
A18: 55 | B18: Biaya PDAM | J18: =SUMIFS(JURNAL_26!$K$9:$K$1764,JURNAL_26!$C$9:$C$1764,'LR BLN'!$N$1,JURNAL_26!$G$9:$G$1764,'LR BLN'!B18) -> 12000
A19: 56 | B19: Biaya WIFI Pos Jaga | J19: =SUMIFS(JURNAL_26!$K$9:$K$1764,JURNAL_26!$C$9:$C$1764,'LR BLN'!$N$1,JURNAL_26!$G$9:$G$1764,'LR BLN'!B19) -> 1070000
A20: 57 | B20: Biaya Kebersihan | J20: =SUMIFS(JURNAL_26!$K$9:$K$1764,JURNAL_26!$C$9:$C$1764,'LR BLN'!$N$1,JURNAL_26!$G$9:$G$1764,'LR BLN'!B20) -> 0
A21: 58 | B21: Biaya adm bank | J21: =SUMIFS(JURNAL_26!$K$9:$K$1764,JURNAL_26!$C$9:$C$1764,'LR BLN'!$N$1,JURNAL_26!$G$9:$G$1764,'LR BLN'!B21) -> 15652
A22: 59 | B22: Biaya iuran RT | J22: =SUMIFS(JURNAL_26!$K$9:$K$1764,JURNAL_26!$C$9:$C$1764,'LR BLN'!$N$1,JURNAL_26!$G$9:$G$1764,'LR BLN'!B22) -> 0
A23: 60 | B23: Biaya Logistik Satpam dan Musholla | J23: =SUMIFS(JURNAL_26!$K$9:$K$1764,JURNAL_26!$C$9:$C$1764,'LR BLN'!$N$1,JURNAL_26!$G$9:$G$1764,'LR BLN'!B23) -> 219000
A24: 61 | B24: Biaya Lain-Lain | J24: =SUMIFS(JURNAL_26!$K$9:$K$1764,JURNAL_26!$C$9:$C$1764,'LR BLN'!$N$1,JURNAL_26!$G$9:$G$1764,'LR BLN'!B24) -> 0
A27: - | B27: Total Pengeluaran | L27: =SUM(J13:K26) -> 6036300
A29: Surplus /Devisit | L29: =L10-L27 -> 373700
J32: Malang, Mei 2026
J33: Disusun Oleh
J38: Andrianto Budiaji

Sheet LR YTD
A1: ='LR BLN'!A1:M1 -> Paguyuban Puri Bunga 2 | N1: ='LR BLN'!N1 -> 5
A2: Laporan Kinerja Keuangan Tahun 2026
A3: ="1 JANUARI s.d. 31 "&VLOOKUP(N1,N3:O14,2,FALSE) -> 1 JANUARI s.d. 31 MEI | N3: 1 | O3: JANUARI
N4: 2 | O4: FEBRUARI
A5: Penerimaan | N5: 3 | O5: MARET
A6: 40 | B6: Penerimaan Iuran Warga | J6: =SUMIFS(JURNAL_26!$J$9:$J$1764,JURNAL_26!$D$9:$D$1764,'LR BLN'!$N$1,JURNAL_26!$G$9:$G$1764,'LR BLN'!B6) -> 27810000 | N6: 4 | O6: APRIL
A7: 41 | B7: Penerimaan Lain-Lain | J7: =SUMIFS(JURNAL_26!$J$9:$J$1764,JURNAL_26!$D$9:$D$1764,'LR BLN'!$N$1,JURNAL_26!$G$9:$G$1764,'LR BLN'!B7) -> 420000 | N7: 5 | O7: MEI
J8: =SUMIFS(JURNAL_26!$J$9:$J$1764,JURNAL_26!$D$9:$D$1764,'LR BLN'!$N$1,JURNAL_26!$G$9:$G$1764,'LR BLN'!B8) -> 0 | N8: 6 | O8: JUNI
J9: =SUMIFS(JURNAL_26!$J$9:$J$1764,JURNAL_26!$D$9:$D$1764,'LR BLN'!$N$1,JURNAL_26!$G$9:$G$1764,'LR BLN'!B9) -> 0 | N9: 7 | O9: JULI
L10: =SUM(J6:K9) -> 28230000 | N10: 8 | O10: AGUSTUS
N11: 9 | O11: SEPTEMBER
A12: Pengeluaran | N12: 10 | O12: OKTOBER
A13: 50 | B13: Biaya Gaji Satpam | J13: =SUMIFS(JURNAL_26!$K$9:$K$1764,JURNAL_26!$D$9:$D$1764,'LR BLN'!$N$1,JURNAL_26!$G$9:$G$1764,'LR BLN'!B13) -> 13028500 | N13: 11 | O13: NOPEMBER
A14: 51 | B14: Biaya Gaji Sampah | J14: =SUMIFS(JURNAL_26!$K$9:$K$1764,JURNAL_26!$D$9:$D$1764,'LR BLN'!$N$1,JURNAL_26!$G$9:$G$1764,'LR BLN'!B14) -> 3450000 | N14: 12 | O14: DESEMBER
A15: 52 | B15: Biaya Gaji Marbot | J15: =SUMIFS(JURNAL_26!$K$9:$K$1764,JURNAL_26!$D$9:$D$1764,'LR BLN'!$N$1,JURNAL_26!$G$9:$G$1764,'LR BLN'!B15) -> 3000000
A16: 53 | B16: Biaya THR | J16: =SUMIFS(JURNAL_26!$K$9:$K$1764,JURNAL_26!$D$9:$D$1764,'LR BLN'!$N$1,JURNAL_26!$G$9:$G$1764,'LR BLN'!B16) -> 3550000
A17: 54 | B17: Biaya Listrik | J17: =SUMIFS(JURNAL_26!$K$9:$K$1764,JURNAL_26!$D$9:$D$1764,'LR BLN'!$N$1,JURNAL_26!$G$9:$G$1764,'LR BLN'!B17) -> 39648
A18: 55 | B18: Biaya PDAM | J18: =SUMIFS(JURNAL_26!$K$9:$K$1764,JURNAL_26!$D$9:$D$1764,'LR BLN'!$N$1,JURNAL_26!$G$9:$G$1764,'LR BLN'!B18) -> 12000
A19: 56 | B19: Biaya WIFI Pos Jaga | J19: =SUMIFS(JURNAL_26!$K$9:$K$1764,JURNAL_26!$D$9:$D$1764,'LR BLN'!$N$1,JURNAL_26!$G$9:$G$1764,'LR BLN'!B19) -> 1300000
A20: 57 | B20: Biaya Kebersihan | J20: =SUMIFS(JURNAL_26!$K$9:$K$1764,JURNAL_26!$D$9:$D$1764,'LR BLN'!$N$1,JURNAL_26!$G$9:$G$1764,'LR BLN'!B20) -> 0
A21: 58 | B21: Biaya adm bank | J21: =SUMIFS(JURNAL_26!$K$9:$K$1764,JURNAL_26!$D$9:$D$1764,'LR BLN'!$N$1,JURNAL_26!$G$9:$G$1764,'LR BLN'!B21) -> 15652
A22: 59 | B22: Biaya iuran RT | J22: =SUMIFS(JURNAL_26!$K$9:$K$1764,JURNAL_26!$D$9:$D$1764,'LR BLN'!$N$1,JURNAL_26!$G$9:$G$1764,'LR BLN'!B22) -> 1500000
A23: 60 | B23: Biaya Logistik Satpam dan Musholla | J23: =SUMIFS(JURNAL_26!$K$9:$K$1764,JURNAL_26!$D$9:$D$1764,'LR BLN'!$N$1,JURNAL_26!$G$9:$G$1764,'LR BLN'!B23) -> 3968000
A24: 61 | B24: Biaya Lain-Lain | J24: =SUMIFS(JURNAL_26!$K$9:$K$1764,JURNAL_26!$D$9:$D$1764,'LR BLN'!$N$1,JURNAL_26!$G$9:$G$1764,'LR BLN'!B24) -> 0
A27: - | B27: Total Pengeluaran | L27: =SUM(J13:K26) -> 29863800
O28: saldo awal tahun | Q28: Neraca | R28: Kas Seharusnya | S28: Saldo kas | T28: Selisih
A29: Surplus /Devisit | L29: =L10-L27 -> -1633800 | O29: =JURNAL_26!L8 -> 8260500 | Q29: ='LAP KAS YTD'!N33 -> 6500000 | R29: =L29+O29+Q29 -> 13126700 | S29: ='LAP KAS BLN'!N38 -> 13126700 | T29: =S29-R29 -> 0
J31: Malang, Mei 2026
J32: Disusun Oleh
J37: Andrianto Budiaji

Sheet LAP KAS BLN
A1: ='LR BLN'!A1:M1 -> Paguyuban Puri Bunga 2 | Q1: ='LR BLN'!N1 -> 5
A2: Laporan Kas Tahun 2026 | U2: otomatis | V2: manual N31
A3: ="BULAN "&VLOOKUP(Q1,Q4:R15,2,FALSE) -> BULAN MEI | T3: SALDO AWAL | U3: LABA/RUGI | V3: NERACA | W3: SALDO AKHIR
A4: ="Per 30 "&VLOOKUP(Q1,$Q$4:$R$15,2,FALSE) -> Per 30 MEI | Q4: 1 | R4: JANUARI | T4: =JURNAL_26!L8 -> 8260500 | U4: ='LR BLN'!S1 -> -965500 | V4: 900000 | W4: =T4+U4+V4 -> 8195000
A5: Kas Kegiatan Operasional | J5: DR | L5: CR | N5: SALDO | Q5: 2 | R5: FEBRUARI | T5: =W4 -> 8195000 | U5: ='LR BLN'!S2 -> 663000 | V5: 2700000 | W5: =T5+U5+V5 -> 11558000
Q6: 3 | R6: MARET | T6: =W5 -> 11558000 | U6: ='LR BLN'!S3 -> -6385000 | V6: 700000 | W6: =T6+U6+V6 -> 5873000
A7: 40 | B7: Penerimaan Iuran Warga | J7: =SUMIFS(JURNAL_26!$J$9:$J$1764,JURNAL_26!$C$9:$C$1764,$Q$1,JURNAL_26!$G$9:$G$1764,B7) -> 6310000 | L7: =SUMIFS(JURNAL_26!$K$9:$K$1764,JURNAL_26!$C$9:$C$1764,$Q$1,JURNAL_26!$G$9:$G$1764,B7) -> 0 | Q7: 4 | R7: APRIL | T7: =W6 -> 5873000 | U7: ='LR BLN'!S4 -> 4680000 | V7: 1400000 | W7: =T7+U7+V7 -> 11953000
A8: 41 | B8: Penerimaan Lain-Lain | J8: =SUMIFS(JURNAL_26!$J$9:$J$1764,JURNAL_26!$C$9:$C$1764,$Q$1,JURNAL_26!$G$9:$G$1764,B8) -> 100000 | L8: =SUMIFS(JURNAL_26!$K$9:$K$1764,JURNAL_26!$C$9:$C$1764,$Q$1,JURNAL_26!$G$9:$G$1764,B8) -> 0 | Q8: 5 | R8: MEI | T8: =W7 -> 11953000 | U8: ='LR BLN'!S5 -> 373700 | V8: =N33 -> 800000 | W8: =T8+U8+V8 -> 13126700
A9: 50 | B9: Biaya Gaji Satpam | J9: =SUMIFS(JURNAL_26!$J$9:$J$1764,JURNAL_26!$C$9:$C$1764,$Q$1,JURNAL_26!$G$9:$G$1764,B9) -> 0 | L9: =SUMIFS(JURNAL_26!$K$9:$K$1764,JURNAL_26!$C$9:$C$1764,$Q$1,JURNAL_26!$G$9:$G$1764,B9) -> 3030000 | Q9: 6 | R9: JUNI | T9: =W8 -> 13126700 | U9: ='LR BLN'!S6 -> 0 | W9: =T9+U9+V9 -> 13126700
A10: 51 | B10: Biaya Gaji Sampah | J10: =SUMIFS(JURNAL_26!$J$9:$J$1764,JURNAL_26!$C$9:$C$1764,$Q$1,JURNAL_26!$G$9:$G$1764,B10) -> 0 | L10: =SUMIFS(JURNAL_26!$K$9:$K$1764,JURNAL_26!$C$9:$C$1764,$Q$1,JURNAL_26!$G$9:$G$1764,B10) -> 900000 | Q10: 7 | R10: JULI | T10: =W9 -> 13126700 | U10: ='LR BLN'!S7 -> 0 | W10: =T10+U10+V10 -> 13126700
A11: 52 | B11: Biaya Gaji Marbot | J11: =SUMIFS(JURNAL_26!$J$9:$J$1764,JURNAL_26!$C$9:$C$1764,$Q$1,JURNAL_26!$G$9:$G$1764,B11) -> 0 | L11: =SUMIFS(JURNAL_26!$K$9:$K$1764,JURNAL_26!$C$9:$C$1764,$Q$1,JURNAL_26!$G$9:$G$1764,B11) -> 750000 | Q11: 8 | R11: AGUSTUS | T11: =W10 -> 13126700 | U11: ='LR BLN'!S8 -> 0 | W11: =T11+U11+V11 -> 13126700
A12: 53 | B12: Biaya THR | J12: =SUMIFS(JURNAL_26!$J$9:$J$1764,JURNAL_26!$C$9:$C$1764,$Q$1,JURNAL_26!$G$9:$G$1764,B12) -> 0 | L12: =SUMIFS(JURNAL_26!$K$9:$K$1764,JURNAL_26!$C$9:$C$1764,$Q$1,JURNAL_26!$G$9:$G$1764,B12) -> 0 | Q12: 9 | R12: SEPTEMBER | T12: =W11 -> 13126700 | U12: ='LR BLN'!S9 -> 0 | W12: =T12+U12+V12 -> 13126700
A13: 54 | B13: Biaya Listrik | J13: =SUMIFS(JURNAL_26!$J$9:$J$1764,JURNAL_26!$C$9:$C$1764,$Q$1,JURNAL_26!$G$9:$G$1764,B13) -> 0 | L13: =SUMIFS(JURNAL_26!$K$9:$K$1764,JURNAL_26!$C$9:$C$1764,$Q$1,JURNAL_26!$G$9:$G$1764,B13) -> 39648 | Q13: 10 | R13: OKTOBER | T13: =W12 -> 13126700 | U13: ='LR BLN'!S10 -> 0 | W13: =T13+U13+V13 -> 13126700
A14: 55 | B14: Biaya PDAM | J14: =SUMIFS(JURNAL_26!$J$9:$J$1764,JURNAL_26!$C$9:$C$1764,$Q$1,JURNAL_26!$G$9:$G$1764,B14) -> 0 | L14: =SUMIFS(JURNAL_26!$K$9:$K$1764,JURNAL_26!$C$9:$C$1764,$Q$1,JURNAL_26!$G$9:$G$1764,B14) -> 12000 | Q14: 11 | R14: NOPEMBER | T14: =W13 -> 13126700 | U14: ='LR BLN'!S11 -> 0 | W14: =T14+U14+V14 -> 13126700
A15: 56 | B15: Biaya WIFI Pos Jaga | J15: =SUMIFS(JURNAL_26!$J$9:$J$1764,JURNAL_26!$C$9:$C$1764,$Q$1,JURNAL_26!$G$9:$G$1764,B15) -> 0 | L15: =SUMIFS(JURNAL_26!$K$9:$K$1764,JURNAL_26!$C$9:$C$1764,$Q$1,JURNAL_26!$G$9:$G$1764,B15) -> 1070000 | Q15: 12 | R15: DESEMBER | T15: =W14 -> 13126700 | U15: ='LR BLN'!S12 -> 0 | W15: =T15+U15+V15 -> 13126700
A16: 57 | B16: Biaya Kebersihan | J16: =SUMIFS(JURNAL_26!$J$9:$J$1764,JURNAL_26!$C$9:$C$1764,$Q$1,JURNAL_26!$G$9:$G$1764,B16) -> 0 | L16: =SUMIFS(JURNAL_26!$K$9:$K$1764,JURNAL_26!$C$9:$C$1764,$Q$1,JURNAL_26!$G$9:$G$1764,B16) -> 0 | U16: =SUM(U4:U15) -> -1633800 | V16: =SUM(V4:V15) -> 6500000
A17: 58 | B17: Biaya adm bank | J17: =SUMIFS(JURNAL_26!$J$9:$J$1764,JURNAL_26!$C$9:$C$1764,$Q$1,JURNAL_26!$G$9:$G$1764,B17) -> 0 | L17: =SUMIFS(JURNAL_26!$K$9:$K$1764,JURNAL_26!$C$9:$C$1764,$Q$1,JURNAL_26!$G$9:$G$1764,B17) -> 15652
A18: 59 | B18: Biaya iuran RT | J18: =SUMIFS(JURNAL_26!$J$9:$J$1764,JURNAL_26!$C$9:$C$1764,$Q$1,JURNAL_26!$G$9:$G$1764,B18) -> 0 | L18: =SUMIFS(JURNAL_26!$K$9:$K$1764,JURNAL_26!$C$9:$C$1764,$Q$1,JURNAL_26!$G$9:$G$1764,B18) -> 0
A19: 60 | B19: Biaya Logistik Satpam dan Musholla | J19: =SUMIFS(JURNAL_26!$J$9:$J$1764,JURNAL_26!$C$9:$C$1764,$Q$1,JURNAL_26!$G$9:$G$1764,B19) -> 0 | L19: =SUMIFS(JURNAL_26!$K$9:$K$1764,JURNAL_26!$C$9:$C$1764,$Q$1,JURNAL_26!$G$9:$G$1764,B19) -> 219000
A20: 61 | B20: Biaya Lain-Lain | J20: =SUMIFS(JURNAL_26!$J$9:$J$1764,JURNAL_26!$C$9:$C$1764,$Q$1,JURNAL_26!$G$9:$G$1764,B20) -> 0 | L20: =SUMIFS(JURNAL_26!$K$9:$K$1764,JURNAL_26!$C$9:$C$1764,$Q$1,JURNAL_26!$G$9:$G$1764,B20) -> 0
J21: =SUMIFS(JURNAL_26!$J$9:$J$1764,JURNAL_26!$C$9:$C$1764,$Q$1,JURNAL_26!$G$9:$G$1764,B21) -> 0 | L21: =SUMIFS(JURNAL_26!$K$9:$K$1764,JURNAL_26!$C$9:$C$1764,$Q$1,JURNAL_26!$G$9:$G$1764,B21) -> 0
J22: =SUMIFS(JURNAL_26!$J$9:$J$1764,JURNAL_26!$C$9:$C$1764,$Q$1,JURNAL_26!$G$9:$G$1764,B22) -> 0 | L22: =SUMIFS(JURNAL_26!$K$9:$K$1764,JURNAL_26!$C$9:$C$1764,$Q$1,JURNAL_26!$G$9:$G$1764,B22) -> 0
B23: Jumlah | J23: =SUM(J6:K22) -> 6410000 | L23: =SUM(L6:M22) -> 6036300 | N23: =J23-L23 -> 373700
A25: Kas Kegiatan Pembiayaan
A26: 10 | B26: Kas dan Bank | J26: =SUMIFS(JURNAL_26!$J$9:$J$1764,JURNAL_26!$C$9:$C$1764,$Q$1,JURNAL_26!$G$9:$G$1764,B26) -> 0 | L26: =SUMIFS(JURNAL_26!$K$9:$K$1764,JURNAL_26!$C$9:$C$1764,$Q$1,JURNAL_26!$G$9:$G$1764,B26) -> 0 | N26: =J26-L26 -> 0
A27: 11 | B27: Kas Kecil | J27: =SUMIFS(JURNAL_26!$J$9:$J$1764,JURNAL_26!$C$9:$C$1764,$Q$1,JURNAL_26!$G$9:$G$1764,B27) -> 0 | L27: =SUMIFS(JURNAL_26!$K$9:$K$1764,JURNAL_26!$C$9:$C$1764,$Q$1,JURNAL_26!$G$9:$G$1764,B27) -> 0 | N27: =J27-L27 -> 0
A28: 12 | B28: Piutang Pembayaran Gaji | J28: =SUMIFS(JURNAL_26!$J$9:$J$1764,JURNAL_26!$C$9:$C$1764,$Q$1,JURNAL_26!$G$9:$G$1764,B28) -> 500000 | L28: =SUMIFS(JURNAL_26!$K$9:$K$1764,JURNAL_26!$C$9:$C$1764,$Q$1,JURNAL_26!$G$9:$G$1764,B28) -> 0 | N28: =J28-L28 -> 500000
